Workbook

Sheet Result
A1: MKS
A2: Current Peak Hour Eps | B2: Increase | C2: Expected EPS/Core | D2: Predicted Avg-LogCPU | E2: CPU | F2: STD | G2: 45 | H2: 50 | I2: 55 | J2: 60 | K2: 65 | L2: 70 | M2: 75 | N2: 80 | O2: 85 | P2: 90 | Q2: 95 | R2: 100
A3: 48 | B3: =C3/A3 -> 1.1458333 | C3: 55 | D3: =CG!$L$2555*C3^3+CG!$M$2555*C3^2+CG!$N$2555*C3+CG!$O$2555 -> 3.9673119 | E3: =EXP(D3) -> 52.842293 | F3: 0.02602383 | G3: =NORMDIST(LN(G$2),$D3,$F3,TRUE) -> 3.3468257e-10 | H3: =NORMDIST(LN(H$2),$D3,$F3,TRUE) -> 0.016812185 | I3: =NORMDIST(LN(I$2),$D3,$F3,TRUE) -> 0.93796 | J3: =NORMDIST(LN(J$2),$D3,$F3,TRUE) -> 0.99999947 | K3: =NORMDIST(LN(K$2),$D3,$F3,TRUE) -> 1 | L3: =NORMDIST(LN(L$2),$D3,$F3,TRUE) -> 1 | M3: =NORMDIST(LN(M$2),$D3,$F3,TRUE) -> 1 | N3: =NORMDIST(LN(N$2),$D3,$F3,TRUE) -> 1 | ... R3: =NORMDIST(LN(R$2),$D3,$F3,TRUE) -> 1
A4: 48 | B4: =C4/A4 -> 1.1666667 | C4: =C3+1 -> 56 | D4: =CG!$L$2555*C4^3+CG!$M$2555*C4^2+CG!$N$2555*C4+CG!$O$2555 -> 3.9945635 | E4: =EXP(D4) -> 54.302133 | F4: 0.02602383 | G4: =NORMDIST(LN(G$2),$D4,$F4,TRUE) -> 2.5928048e-13 | H4: =NORMDIST(LN(H$2),$D4,$F4,TRUE) -> 0.00075767541 | I4: =NORMDIST(LN(I$2),$D4,$F4,TRUE) -> 0.68817777 | J4: =NORMDIST(LN(J$2),$D4,$F4,TRUE) -> 0.99993702 | K4: =NORMDIST(LN(K$2),$D4,$F4,TRUE) -> 1 | L4: =NORMDIST(LN(L$2),$D4,$F4,TRUE) -> 1 | M4: =NORMDIST(LN(M$2),$D4,$F4,TRUE) -> 1 | N4: =NORMDIST(LN(N$2),$D4,$F4,TRUE) -> 1 | ... R4: =NORMDIST(LN(R$2),$D4,$F4,TRUE) -> 1
A5: 48 | B5: =C5/A5 -> 1.1875 | C5: =C4+1 -> 57 | D5: =CG!$L$2555*C5^3+CG!$M$2555*C5^2+CG!$N$2555*C5+CG!$O$2555 -> 4.0235108 | E5: =EXP(D5) -> 55.897005 | F5: 0.02602383 | G5: =NORMDIST(LN(G$2),$D5,$F5,TRUE) -> 3.9515465e-17 | H5: =NORMDIST(LN(H$2),$D5,$F5,TRUE) -> 9.1754346e-06 | I5: =NORMDIST(LN(I$2),$D5,$F5,TRUE) -> 0.26708722 | J5: =NORMDIST(LN(J$2),$D5,$F5,TRUE) -> 0.99675442 | K5: =NORMDIST(LN(K$2),$D5,$F5,TRUE) -> 1 | L5: =NORMDIST(LN(L$2),$D5,$F5,TRUE) -> 1 | M5: =NORMDIST(LN(M$2),$D5,$F5,TRUE) -> 1 | N5: =NORMDIST(LN(N$2),$D5,$F5,TRUE) -> 1 | ... R5: =NORMDIST(LN(R$2),$D5,$F5,TRUE) -> 1
A6: 48 | B6: =C6/A6 -> 1.2083333 | C6: =C5+1 -> 58 | D6: =CG!$L$2555*C6^3+CG!$M$2555*C6^2+CG!$N$2555*C6+CG!$O$2555 -> 4.054322 | E6: =EXP(D6) -> 57.646064 | F6: 0.02602383 | G6: =NORMDIST(LN(G$2),$D6,$F6,TRUE) -> 8.9432835e-22 | H6: =NORMDIST(LN(H$2),$D6,$F6,TRUE) -> 2.2753869e-08 | I6: =NORMDIST(LN(I$2),$D6,$F6,TRUE) -> 0.03548997 | J6: =NORMDIST(LN(J$2),$D6,$F6,TRUE) -> 0.93796605 | K6: =NORMDIST(LN(K$2),$D6,$F6,TRUE) -> 0.99999802 | L6: =NORMDIST(LN(L$2),$D6,$F6,TRUE) -> 1 | M6: =NORMDIST(LN(M$2),$D6,$F6,TRUE) -> 1 | N6: =NORMDIST(LN(N$2),$D6,$F6,TRUE) -> 1 | ... R6: =NORMDIST(LN(R$2),$D6,$F6,TRUE) -> 1
A7: 48 | B7: =C7/A7 -> 1.2291667 | C7: =C6+1 -> 59 | D7: =CG!$L$2555*C7^3+CG!$M$2555*C7^2+CG!$N$2555*C7+CG!$O$2555 -> 4.0871652 | E7: =EXP(D7) -> 59.57078 | F7: 0.02602383 | G7: =NORMDIST(LN(G$2),$D7,$F7,TRUE) -> 2.1702136e-27 | H7: =NORMDIST(LN(H$2),$D7,$F7,TRUE) -> 8.4791335e-12 | I7: =NORMDIST(LN(I$2),$D7,$F7,TRUE) -> 0.0010787471 | J7: =NORMDIST(LN(J$2),$D7,$F7,TRUE) -> 0.60867884 | K7: =NORMDIST(LN(K$2),$D7,$F7,TRUE) -> 0.9995983 | L7: =NORMDIST(LN(L$2),$D7,$F7,TRUE) -> 1 | M7: =NORMDIST(LN(M$2),$D7,$F7,TRUE) -> 1 | N7: =NORMDIST(LN(N$2),$D7,$F7,TRUE) -> 1 | ... R7: =NORMDIST(LN(R$2),$D7,$F7,TRUE) -> 1
A8: 48 | B8: =C8/A8 -> 1.25 | C8: =C7+1 -> 60 | D8: =CG!$L$2555*C8^3+CG!$M$2555*C8^2+CG!$N$2555*C8+CG!$O$2555 -> 4.1222086 | E8: =EXP(D8) -> 61.695355 | F8: 0.02602383 | G8: =NORMDIST(LN(G$2),$D8,$F8,TRUE) -> 3.8798641e-34 | H8: =NORMDIST(LN(H$2),$D8,$F8,TRUE) -> 3.3282308e-16 | I8: =NORMDIST(LN(I$2),$D8,$F8,TRUE) -> 5.0682496e-06 | J8: =NORMDIST(LN(J$2),$D8,$F8,TRUE) -> 0.142149 | K8: =NORMDIST(LN(K$2),$D8,$F8,TRUE) -> 0.97752021 | L8: =NORMDIST(LN(L$2),$D8,$F8,TRUE) -> 0.99999939 | M8: =NORMDIST(LN(M$2),$D8,$F8,TRUE) -> 1 | N8: =NORMDIST(LN(N$2),$D8,$F8,TRUE) -> 1 | ... R8: =NORMDIST(LN(R$2),$D8,$F8,TRUE) -> 1
A9: 48 | B9: =C9/A9 -> 1.2708333 | C9: =C8+1 -> 61 | D9: =CG!$L$2555*C9^3+CG!$M$2555*C9^2+CG!$N$2555*C9+CG!$O$2555 -> 4.1596206 | E9: =EXP(D9) -> 64.047215 | F9: 0.02602383 | G9: =NORMDIST(LN(G$2),$D9,$F9,TRUE) -> 3.3237385e-42 | H9: =NORMDIST(LN(H$2),$D9,$F9,TRUE) -> 9.1503345e-22 | I9: =NORMDIST(LN(I$2),$D9,$F9,TRUE) -> 2.4307779e-09 | J9: =NORMDIST(LN(J$2),$D9,$F9,TRUE) -> 0.0060654056 | K9: =NORMDIST(LN(K$2),$D9,$F9,TRUE) -> 0.71478915 | L9: =NORMDIST(LN(L$2),$D9,$F9,TRUE) -> 0.99968124 | M9: =NORMDIST(LN(M$2),$D9,$F9,TRUE) -> 1 | N9: =NORMDIST(LN(N$2),$D9,$F9,TRUE) -> 1 | ... R9: =NORMDIST(LN(R$2),$D9,$F9,TRUE) -> 1
A10: 48 | B10: =C10/A10 -> 1.2916667 | C10: =C9+1 -> 62 | D10: =CG!$L$2555*C10^3+CG!$M$2555*C10^2+CG!$N$2555*C10+CG!$O$2555 -> 4.1995691 | E10: =EXP(D10) -> 66.657602 | F10: 0.02602383 | G10: =NORMDIST(LN(G$2),$D10,$F10,TRUE) -> 8.3517307e-52 | H10: =NORMDIST(LN(H$2),$D10,$F10,TRUE) -> 1.1041871e-28 | I10: =NORMDIST(LN(I$2),$D10,$F10,TRUE) -> 7.5135261e-14 | J10: =NORMDIST(LN(J$2),$D10,$F10,TRUE) -> 2.6341749e-05 | K10: =NORMDIST(LN(K$2),$D10,$F10,TRUE) -> 0.16661082 | L10: =NORMDIST(LN(L$2),$D10,$F10,TRUE) -> 0.96994947 | M10: =NORMDIST(LN(M$2),$D10,$F10,TRUE) -> 0.99999707 | N10: =NORMDIST(LN(N$2),$D10,$F10,TRUE) -> 1 | ... R10: =NORMDIST(LN(R$2),$D10,$F10,TRUE) -> 1
A11: 48 | B11: =C11/A11 -> 1.3125 | C11: =C10+1 -> 63 | D11: =CG!$L$2555*C11^3+CG!$M$2555*C11^2+CG!$N$2555*C11+CG!$O$2555 -> 4.2422225 | E11: =EXP(D11) -> 69.562281 | F11: 0.02602383 | G11: =NORMDIST(LN(G$2),$D11,$F11,TRUE) -> 3.5244673e-63 | H11: =NORMDIST(LN(H$2),$D11,$F11,TRUE) -> 3.4307884e-37 | I11: =NORMDIST(LN(I$2),$D11,$F11,TRUE) -> 8.9086882e-20 | J11: =NORMDIST(LN(J$2),$D11,$F11,TRUE) -> 6.6407187e-09 | K11: =NORMDIST(LN(K$2),$D11,$F11,TRUE) -> 0.0045715379 | L11: =NORMDIST(LN(L$2),$D11,$F11,TRUE) -> 0.59523757 | M11: =NORMDIST(LN(M$2),$D11,$F11,TRUE) -> 0.99808711 | N11: =NORMDIST(LN(N$2),$D11,$F11,TRUE) -> 0.99999996 | ... R11: =NORMDIST(LN(R$2),$D11,$F11,TRUE) -> 1
A12: 48 | B12: =C12/A12 -> 1.3333333 | C12: =C11+1 -> 64 | D12: =CG!$L$2555*C12^3+CG!$M$2555*C12^2+CG!$N$2555*C12+CG!$O$2555 -> 4.2877489 | E12: =EXP(D12) -> 72.802398 | F12: 0.02602383 | G12: =NORMDIST(LN(G$2),$D12,$F12,TRUE) -> 1.3290665e-76 | H12: =NORMDIST(LN(H$2),$D12,$F12,TRUE) -> 1.4970207e-47 | I12: =NORMDIST(LN(I$2),$D12,$F12,TRUE) -> 2.2504989e-27 | J12: =NORMDIST(LN(J$2),$D12,$F12,TRUE) -> 5.3558201e-14 | K12: =NORMDIST(LN(K$2),$D12,$F12,TRUE) -> 6.6209279e-06 | L12: =NORMDIST(LN(L$2),$D12,$F12,TRUE) -> 0.065729512 | M12: =NORMDIST(LN(M$2),$D12,$F12,TRUE) -> 0.87343271 | N12: =NORMDIST(LN(N$2),$D12,$F12,TRUE) -> 0.99985425 | ... R12: =NORMDIST(LN(R$2),$D12,$F12,TRUE) -> 1
A13: 48 | B13: =C13/A13 -> 1.3541667 | C13: =C12+1 -> 65 | D13: =CG!$L$2555*C13^3+CG!$M$2555*C13^2+CG!$N$2555*C13+CG!$O$2555 -> 4.3363165 | E13: =EXP(D13) -> 76.425509 | F13: 0.02602383 | G13: =NORMDIST(LN(G$2),$D13,$F13,TRUE) -> 2.1989993e-92 | H13: =NORMDIST(LN(H$2),$D13,$F13,TRUE) -> 4.6191034e-60 | I13: =NORMDIST(LN(I$2),$D13,$F13,TRUE) -> 6.2232539e-37 | J13: =NORMDIST(LN(J$2),$D13,$F13,TRUE) -> 7.1494465e-21 | K13: =NORMDIST(LN(K$2),$D13,$F13,TRUE) -> 2.4488918e-10 | L13: =NORMDIST(LN(L$2),$D13,$F13,TRUE) -> 0.00036955013 | M13: =NORMDIST(LN(M$2),$D13,$F13,TRUE) -> 0.2346844 | N13: =NORMDIST(LN(N$2),$D13,$F13,TRUE) -> 0.96049602 | ... R13: =NORMDIST(LN(R$2),$D13,$F13,TRUE) -> 1
A14: 48 | B14: =C14/A14 -> 1.375 | C14: =C13+1 -> 66 | D14: =CG!$L$2555*C14^3+CG!$M$2555*C14^2+CG!$N$2555*C14+CG!$O$2555 -> 4.3880936 | E14: =EXP(D14) -> 80.48683 | F14: 0.02602383 | G14: =NORMDIST(LN(G$2),$D14,$F14,TRUE) -> 7.1802357e-111 | H14: =NORMDIST(LN(H$2),$D14,$F14,TRUE) -> 4.6497141e-75 | I14: =NORMDIST(LN(I$2),$D14,$F14,TRUE) -> 8.8787243e-49 | J14: =NORMDIST(LN(J$2),$D14,$F14,TRUE) -> 7.5473369e-30 | K14: =NORMDIST(LN(K$2),$D14,$F14,TRUE) -> 1.0881574e-16 | L14: =NORMDIST(LN(L$2),$D14,$F14,TRUE) -> 4.0643172e-08 | M14: =NORMDIST(LN(M$2),$D14,$F14,TRUE) -> 0.0033327717 | N14: =NORMDIST(LN(N$2),$D14,$F14,TRUE) -> 0.40783025 | ... R14: =NORMDIST(LN(R$2),$D14,$F14,TRUE) -> 1
A15: 48 | B15: =C15/A15 -> 1.3958333 | C15: =C14+1 -> 67 | D15: =CG!$L$2555*C15^3+CG!$M$2555*C15^2+CG!$N$2555*C15+CG!$O$2555 -> 4.4432482 | E15: =EXP(D15) -> 85.050758 | F15: 0.02602383 | G15: =NORMDIST(LN(G$2),$D15,$F15,TRUE) -> 1.891651e-132 | H15: =NORMDIST(LN(H$2),$D15,$F15,TRUE) -> 6.4046608e-93 | I15: =NORMDIST(LN(I$2),$D15,$F15,TRUE) -> 2.8024159e-63 | J15: =NORMDIST(LN(J$2),$D15,$F15,TRUE) -> 2.7478985e-41 | K15: =NORMDIST(LN(K$2),$D15,$F15,TRUE) -> 2.5423481e-25 | L15: =NORMDIST(LN(L$2),$D15,$F15,TRUE) -> 3.6145841e-14 | M15: =NORMDIST(LN(M$2),$D15,$F15,TRUE) -> 6.7415192e-07 | N15: =NORMDIST(LN(N$2),$D15,$F15,TRUE) -> 0.009323334 | ... R15: =NORMDIST(LN(R$2),$D15,$F15,TRUE) -> 1
... A23: 48 | B23: =C23/A23 -> 1.5625 | C23: =C22+1 -> 75 | D23: =CG!$L$2555*C23^3+CG!$M$2555*C23^2+CG!$N$2555*C23+CG!$O$2555 -> 5.0262628 | E23: =EXP(D23) -> 152.36254 | F23: 0.02602383 | G23: =NORMDIST(LN(G$2),$D23,$F23,TRUE) -> 0 | H23: =NORMDIST(LN(H$2),$D23,$F23,TRUE) -> 0 | I23: =NORMDIST(LN(I$2),$D23,$F23,TRUE) -> 0 | J23: =NORMDIST(LN(J$2),$D23,$F23,TRUE) -> 3.8333129e-281 | K23: =NORMDIST(LN(K$2),$D23,$F23,TRUE) -> 2.5279741e-235 | L23: =NORMDIST(LN(L$2),$D23,$F23,TRUE) -> 1.4630033e-196 | M23: =NORMDIST(LN(M$2),$D23,$F23,TRUE) -> 1.2306864e-163 | N23: =NORMDIST(LN(N$2),$D23,$F23,TRUE) -> 1.3484041e-135 | ... R23: =NORMDIST(LN(R$2),$D23,$F23,TRUE) -> 3.4313624e-59
A26: TBS
A27: Current Peak Hour Eps | B27: Increase | C27: Expected EPS/Core | D27: Predicted Avg-LogCPU | E27: CPU | F27: STD | G27: 45 | H27: 50 | I27: 55 | J27: 60 | K27: 65 | L27: 70 | M27: 75 | N27: 80 | O27: 85 | P27: 90 | Q27: 95 | R27: 100
A28: 38 | B28: =C28/A28 -> 1.4473684 | C28: 55 | D28: =CG!$L$2555*C28^3+CG!$M$2555*C28^2+CG!$N$2555*C28+CG!$O$2555 -> 3.9673119 | E28: =EXP(D28) -> 52.842293 | F28: 0.02602383 | G28: =NORMDIST(LN(G$27),$D28,$F28,TRUE) -> 3.3468257e-10 | H28: =NORMDIST(LN(H$27),$D28,$F28,TRUE) -> 0.016812185 | I28: =NORMDIST(LN(I$27),$D28,$F28,TRUE) -> 0.93796 | J28: =NORMDIST(LN(J$27),$D28,$F28,TRUE) -> 0.99999947 | K28: =NORMDIST(LN(K$27),$D28,$F28,TRUE) -> 1 | L28: =NORMDIST(LN(L$27),$D28,$F28,TRUE) -> 1 | M28: =NORMDIST(LN(M$27),$D28,$F28,TRUE) -> 1 | N28: =NORMDIST(LN(N$27),$D28,$F28,TRUE) -> 1 | ... R28: =NORMDIST(LN(R$27),$D28,$F28,TRUE) -> 1
A29: 38 | B29: =C29/A29 -> 1.4736842 | C29: =C28+1 -> 56 | D29: =CG!$L$2555*C29^3+CG!$M$2555*C29^2+CG!$N$2555*C29+CG!$O$2555 -> 3.9945635 | E29: =EXP(D29) -> 54.302133 | F29: 0.02602383 | G29: =NORMDIST(LN(G$27),$D29,$F29,TRUE) -> 2.5928048e-13 | H29: =NORMDIST(LN(H$27),$D29,$F29,TRUE) -> 0.00075767541 | I29: =NORMDIST(LN(I$27),$D29,$F29,TRUE) -> 0.68817777 | J29: =NORMDIST(LN(J$27),$D29,$F29,TRUE) -> 0.99993702 | K29: =NORMDIST(LN(K$27),$D29,$F29,TRUE) -> 1 | L29: =NORMDIST(LN(L$27),$D29,$F29,TRUE) -> 1 | M29: =NORMDIST(LN(M$27),$D29,$F29,TRUE) -> 1 | N29: =NORMDIST(LN(N$27),$D29,$F29,TRUE) -> 1 | ... R29: =NORMDIST(LN(R$27),$D29,$F29,TRUE) -> 1
A30: 38 | B30: =C30/A30 -> 1.5 | C30: =C29+1 -> 57 | D30: =CG!$L$2555*C30^3+CG!$M$2555*C30^2+CG!$N$2555*C30+CG!$O$2555 -> 4.0235108 | E30: =EXP(D30) -> 55.897005 | F30: 0.02602383 | G30: =NORMDIST(LN(G$27),$D30,$F30,TRUE) -> 3.9515465e-17 | H30: =NORMDIST(LN(H$27),$D30,$F30,TRUE) -> 9.1754346e-06 | I30: =NORMDIST(LN(I$27),$D30,$F30,TRUE) -> 0.26708722 | J30: =NORMDIST(LN(J$27),$D30,$F30,TRUE) -> 0.99675442 | K30: =NORMDIST(LN(K$27),$D30,$F30,TRUE) -> 1 | L30: =NORMDIST(LN(L$27),$D30,$F30,TRUE) -> 1 | M30: =NORMDIST(LN(M$27),$D30,$F30,TRUE) -> 1 | N30: =NORMDIST(LN(N$27),$D30,$F30,TRUE) -> 1 | ... R30: =NORMDIST(LN(R$27),$D30,$F30,TRUE) -> 1
A31: 38 | B31: =C31/A31 -> 1.5263158 | C31: =C30+1 -> 58 | D31: =CG!$L$2555*C31^3+CG!$M$2555*C31^2+CG!$N$2555*C31+CG!$O$2555 -> 4.054322 | E31: =EXP(D31) -> 57.646064 | F31: 0.02602383 | G31: =NORMDIST(LN(G$27),$D31,$F31,TRUE) -> 8.9432835e-22 | H31: =NORMDIST(LN(H$27),$D31,$F31,TRUE) -> 2.2753869e-08 | I31: =NORMDIST(LN(I$27),$D31,$F31,TRUE) -> 0.03548997 | J31: =NORMDIST(LN(J$27),$D31,$F31,TRUE) -> 0.93796605 | K31: =NORMDIST(LN(K$27),$D31,$F31,TRUE) -> 0.99999802 | L31: =NORMDIST(LN(L$27),$D31,$F31,TRUE) -> 1 | M31: =NORMDIST(LN(M$27),$D31,$F31,TRUE) -> 1 | N31: =NORMDIST(LN(N$27),$D31,$F31,TRUE) -> 1 | ... R31: =NORMDIST(LN(R$27),$D31,$F31,TRUE) -> 1
A32: 38 | B32: =C32/A32 -> 1.5526316 | C32: =C31+1 -> 59 | D32: =CG!$L$2555*C32^3+CG!$M$2555*C32^2+CG!$N$2555*C32+CG!$O$2555 -> 4.0871652 | E32: =EXP(D32) -> 59.57078 | F32: 0.02602383 | G32: =NORMDIST(LN(G$27),$D32,$F32,TRUE) -> 2.1702136e-27 | H32: =NORMDIST(LN(H$27),$D32,$F32,TRUE) -> 8.4791335e-12 | I32: =NORMDIST(LN(I$27),$D32,$F32,TRUE) -> 0.0010787471 | J32: =NORMDIST(LN(J$27),$D32,$F32,TRUE) -> 0.60867884 | K32: =NORMDIST(LN(K$27),$D32,$F32,TRUE) -> 0.9995983 | L32: =NORMDIST(LN(L$27),$D32,$F32,TRUE) -> 1 | M32: =NORMDIST(LN(M$27),$D32,$F32,TRUE) -> 1 | N32: =NORMDIST(LN(N$27),$D32,$F32,TRUE) -> 1 | ... R32: =NORMDIST(LN(R$27),$D32,$F32,TRUE) -> 1
A33: 38 | B33: =C33/A33 -> 1.5789474 | C33: =C32+1 -> 60 | D33: =CG!$L$2555*C33^3+CG!$M$2555*C33^2+CG!$N$2555*C33+CG!$O$2555 -> 4.1222086 | E33: =EXP(D33) -> 61.695355 | F33: 0.02602383 | G33: =NORMDIST(LN(G$27),$D33,$F33,TRUE) -> 3.8798641e-34 | H33: =NORMDIST(LN(H$27),$D33,$F33,TRUE) -> 3.3282308e-16 | I33: =NORMDIST(LN(I$27),$D33,$F33,TRUE) -> 5.0682496e-06 | J33: =NORMDIST(LN(J$27),$D33,$F33,TRUE) -> 0.142149 | K33: =NORMDIST(LN(K$27),$D33,$F33,TRUE) -> 0.97752021 | L33: =NORMDIST(LN(L$27),$D33,$F33,TRUE) -> 0.99999939 | M33: =NORMDIST(LN(M$27),$D33,$F33,TRUE) -> 1 | N33: =NORMDIST(LN(N$27),$D33,$F33,TRUE) -> 1 | ... R33: =NORMDIST(LN(R$27),$D33,$F33,TRUE) -> 1
A34: 38 | B34: =C34/A34 -> 1.6052632 | C34: =C33+1 -> 61 | D34: =CG!$L$2555*C34^3+CG!$M$2555*C34^2+CG!$N$2555*C34+CG!$O$2555 -> 4.1596206 | E34: =EXP(D34) -> 64.047215 | F34: 0.02602383 | G34: =NORMDIST(LN(G$27),$D34,$F34,TRUE) -> 3.3237385e-42 | H34: =NORMDIST(LN(H$27),$D34,$F34,TRUE) -> 9.1503345e-22 | I34: =NORMDIST(LN(I$27),$D34,$F34,TRUE) -> 2.4307779e-09 | J34: =NORMDIST(LN(J$27),$D34,$F34,TRUE) -> 0.0060654056 | K34: =NORMDIST(LN(K$27),$D34,$F34,TRUE) -> 0.71478915 | L34: =NORMDIST(LN(L$27),$D34,$F34,TRUE) -> 0.99968124 | M34: =NORMDIST(LN(M$27),$D34,$F34,TRUE) -> 1 | N34: =NORMDIST(LN(N$27),$D34,$F34,TRUE) -> 1 | ... R34: =NORMDIST(LN(R$27),$D34,$F34,TRUE) -> 1
A35: 38 | B35: =C35/A35 -> 1.6315789 | C35: =C34+1 -> 62 | D35: =CG!$L$2555*C35^3+CG!$M$2555*C35^2+CG!$N$2555*C35+CG!$O$2555 -> 4.1995691 | E35: =EXP(D35) -> 66.657602 | F35: 0.02602383 | G35: =NORMDIST(LN(G$27),$D35,$F35,TRUE) -> 8.3517307e-52 | H35: =NORMDIST(LN(H$27),$D35,$F35,TRUE) -> 1.1041871e-28 | I35: =NORMDIST(LN(I$27),$D35,$F35,TRUE) -> 7.5135261e-14 | J35: =NORMDIST(LN(J$27),$D35,$F35,TRUE) -> 2.6341749e-05 | K35: =NORMDIST(LN(K$27),$D35,$F35,TRUE) -> 0.16661082 | L35: =NORMDIST(LN(L$27),$D35,$F35,TRUE) -> 0.96994947 | M35: =NORMDIST(LN(M$27),$D35,$F35,TRUE) -> 0.99999707 | N35: =NORMDIST(LN(N$27),$D35,$F35,TRUE) -> 1 | ... R35: =NORMDIST(LN(R$27),$D35,$F35,TRUE) -> 1
A36: 38 | B36: =C36/A36 -> 1.6578947 | C36: =C35+1 -> 63 | D36: =CG!$L$2555*C36^3+CG!$M$2555*C36^2+CG!$N$2555*C36+CG!$O$2555 -> 4.2422225 | E36: =EXP(D36) -> 69.562281 | F36: 0.02602383 | G36: =NORMDIST(LN(G$27),$D36,$F36,TRUE) -> 3.5244673e-63 | H36: =NORMDIST(LN(H$27),$D36,$F36,TRUE) -> 3.4307884e-37 | I36: =NORMDIST(LN(I$27),$D36,$F36,TRUE) -> 8.9086882e-20 | J36: =NORMDIST(LN(J$27),$D36,$F36,TRUE) -> 6.6407187e-09 | K36: =NORMDIST(LN(K$27),$D36,$F36,TRUE) -> 0.0045715379 | L36: =NORMDIST(LN(L$27),$D36,$F36,TRUE) -> 0.59523757 | M36: =NORMDIST(LN(M$27),$D36,$F36,TRUE) -> 0.99808711 | N36: =NORMDIST(LN(N$27),$D36,$F36,TRUE) -> 0.99999996 | ... R36: =NORMDIST(LN(R$27),$D36,$F36,TRUE) -> 1
A37: 38 | B37: =C37/A37 -> 1.6842105 | C37: =C36+1 -> 64 | D37: =CG!$L$2555*C37^3+CG!$M$2555*C37^2+CG!$N$2555*C37+CG!$O$2555 -> 4.2877489 | E37: =EXP(D37) -> 72.802398 | F37: 0.02602383 | G37: =NORMDIST(LN(G$27),$D37,$F37,TRUE) -> 1.3290665e-76 | H37: =NORMDIST(LN(H$27),$D37,$F37,TRUE) -> 1.4970207e-47 | I37: =NORMDIST(LN(I$27),$D37,$F37,TRUE) -> 2.2504989e-27 | J37: =NORMDIST(LN(J$27),$D37,$F37,TRUE) -> 5.3558201e-14 | K37: =NORMDIST(LN(K$27),$D37,$F37,TRUE) -> 6.6209279e-06 | L37: =NORMDIST(LN(L$27),$D37,$F37,TRUE) -> 0.065729512 | M37: =NORMDIST(LN(M$27),$D37,$F37,TRUE) -> 0.87343271 | N37: =NORMDIST(LN(N$27),$D37,$F37,TRUE) -> 0.99985425 | ... R37: =NORMDIST(LN(R$27),$D37,$F37,TRUE) -> 1
A38: 38 | B38: =C38/A38 -> 1.7105263 | C38: =C37+1 -> 65 | D38: =CG!$L$2555*C38^3+CG!$M$2555*C38^2+CG!$N$2555*C38+CG!$O$2555 -> 4.3363165 | E38: =EXP(D38) -> 76.425509 | F38: 0.02602383 | G38: =NORMDIST(LN(G$27),$D38,$F38,TRUE) -> 2.1989993e-92 | H38: =NORMDIST(LN(H$27),$D38,$F38,TRUE) -> 4.6191034e-60 | I38: =NORMDIST(LN(I$27),$D38,$F38,TRUE) -> 6.2232539e-37 | J38: =NORMDIST(LN(J$27),$D38,$F38,TRUE) -> 7.1494465e-21 | K38: =NORMDIST(LN(K$27),$D38,$F38,TRUE) -> 2.4488918e-10 | L38: =NORMDIST(LN(L$27),$D38,$F38,TRUE) -> 0.00036955013 | M38: =NORMDIST(LN(M$27),$D38,$F38,TRUE) -> 0.2346844 | N38: =NORMDIST(LN(N$27),$D38,$F38,TRUE) -> 0.96049602 | ... R38: =NORMDIST(LN(R$27),$D38,$F38,TRUE) -> 1
A39: 38 | B39: =C39/A39 -> 1.7368421 | C39: =C38+1 -> 66 | D39: =CG!$L$2555*C39^3+CG!$M$2555*C39^2+CG!$N$2555*C39+CG!$O$2555 -> 4.3880936 | E39: =EXP(D39) -> 80.48683 | F39: 0.02602383 | G39: =NORMDIST(LN(G$27),$D39,$F39,TRUE) -> 7.1802357e-111 | H39: =NORMDIST(LN(H$27),$D39,$F39,TRUE) -> 4.6497141e-75 | I39: =NORMDIST(LN(I$27),$D39,$F39,TRUE) -> 8.8787243e-49 | J39: =NORMDIST(LN(J$27),$D39,$F39,TRUE) -> 7.5473369e-30 | K39: =NORMDIST(LN(K$27),$D39,$F39,TRUE) -> 1.0881574e-16 | L39: =NORMDIST(LN(L$27),$D39,$F39,TRUE) -> 4.0643172e-08 | M39: =NORMDIST(LN(M$27),$D39,$F39,TRUE) -> 0.0033327717 | N39: =NORMDIST(LN(N$27),$D39,$F39,TRUE) -> 0.40783025 | ... R39: =NORMDIST(LN(R$27),$D39,$F39,TRUE) -> 1
A40: 38 | B40: =C40/A40 -> 1.7631579 | C40: =C39+1 -> 67 | D40: =CG!$L$2555*C40^3+CG!$M$2555*C40^2+CG!$N$2555*C40+CG!$O$2555 -> 4.4432482 | E40: =EXP(D40) -> 85.050758 | F40: 0.02602383 | G40: =NORMDIST(LN(G$27),$D40,$F40,TRUE) -> 1.891651e-132 | H40: =NORMDIST(LN(H$27),$D40,$F40,TRUE) -> 6.4046608e-93 | I40: =NORMDIST(LN(I$27),$D40,$F40,TRUE) -> 2.8024159e-63 | J40: =NORMDIST(LN(J$27),$D40,$F40,TRUE) -> 2.7478985e-41 | K40: =NORMDIST(LN(K$27),$D40,$F40,TRUE) -> 2.5423481e-25 | L40: =NORMDIST(LN(L$27),$D40,$F40,TRUE) -> 3.6145841e-14 | M40: =NORMDIST(LN(M$27),$D40,$F40,TRUE) -> 6.7415192e-07 | N40: =NORMDIST(LN(N$27),$D40,$F40,TRUE) -> 0.009323334 | ... R40: =NORMDIST(LN(R$27),$D40,$F40,TRUE) -> 1
... A48: 38 | B48: =C48/A48 -> 1.9736842 | C48: =C47+1 -> 75 | D48: =CG!$L$2555*C48^3+CG!$M$2555*C48^2+CG!$N$2555*C48+CG!$O$2555 -> 5.0262628 | E48: =EXP(D48) -> 152.36254 | F48: 0.02602383 | G48: =NORMDIST(LN(G$27),$D48,$F48,TRUE) -> 0 | H48: =NORMDIST(LN(H$27),$D48,$F48,TRUE) -> 0 | I48: =NORMDIST(LN(I$27),$D48,$F48,TRUE) -> 0 | J48: =NORMDIST(LN(J$27),$D48,$F48,TRUE) -> 3.8333129e-281 | K48: =NORMDIST(LN(K$27),$D48,$F48,TRUE) -> 2.5279741e-235 | L48: =NORMDIST(LN(L$27),$D48,$F48,TRUE) -> 1.4630033e-196 | M48: =NORMDIST(LN(M$27),$D48,$F48,TRUE) -> 1.2306864e-163 | N48: =NORMDIST(LN(N$27),$D48,$F48,TRUE) -> 1.3484041e-135 | ... R48: =NORMDIST(LN(R$27),$D48,$F48,TRUE) -> 3.4313624e-59
C52: Current Daily Events(M) | D52: Increase | E52: Estimated Daily Events(m)
B53: MKS | C53: =377201412/1000000 -> 377.20141 | D53: 1.3 | E53: =C53*D53 -> 490.36184
B54: TBS | C54: =293274953/1000000 -> 293.27495 | D54: 1.6 | E54: =C54*D54 -> 469.23992
C55: =C53+C54 -> 670.47636 | E55: =E53+E54 -> 959.60176
B57: Subscribers | C57: 23.5 | D57: =E55/C55 -> 1.4312238 | E57: =C57*D57 -> 33.63376

Sheet Sheet1
A3: Row Labels | B3: Average of EPS/core
A4: 0.25 | B4: 16.617551
A5: 0.5 | B5: 12.983807
A6: 0.75 | B6: 10.397696
A7: 1 | B7: 8.5956629
A8: 1.25 | B8: 7.9943434
A9: 1.5 | B9: 6.5429167
A10: 1.75 | B10: 5.9156692
A11: 2 | B11: 5.1248232
A12: 2.25 | B12: 4.5439268
A13: 2.5 | B13: 3.8264962
A14: 2.75 | B14: 3.5124937
A15: 3 | B15: 3.2134659
... A99: 24 | B99: 21.788138
A100: Grand Total | B100: 24.805438

Sheet MKS Pivot
B3: Values
A4: Row Labels | B4: Average of EPS/core | C4: StdDev of EPS/core2 | D4: Average of AvgOfLogs | E4: StdDev of AvgOfLogs2 | F4: Average of CPU average (15 min) | G4: Average of LogOfAvg | H4: StdDev of LogOfAvg
A5: 0.25 | B5: 16.617551 | C5: 0.18732762 | D5: 3.5300289 | E5: 0.084911552 | F5: 38.163182 | G5: 3.6384816 | H5: 0.087773373
A6: 0.5 | B6: 12.983807 | C6: 0.15249558 | D6: 3.5560428 | E6: 0.2547839 | F6: 36.082121 | G6: 3.5579959 | H6: 0.25331059
A7: 0.75 | B7: 10.397696 | C7: 0.12482638 | D7: 2.7870498 | E7: 0.1995707 | F7: 16.814394 | G7: 2.8039753 | H7: 0.20149703
A8: 1 | B8: 8.5956629 | C8: 0.10283803 | D8: 2.6405184 | E8: 0.058205144 | F8: 14.919697 | G8: 2.7009911 | H8: 0.059603853
A9: 1.25 | B9: 7.9943434 | C9: 0.14537751 | D9: 2.4965221 | E9: 0.14906202 | F9: 12.784394 | G9: 2.5374811 | H9: 0.15391511
A10: 1.5 | B10: 6.5429167 | C10: 0.1286475 | D10: 2.6166587 | E10: 0.21129835 | F10: 14.018485 | G10: 2.6223127 | H10: 0.20993759
A11: 1.75 | B11: 5.9156692 | C11: 0.1035324 | D11: 2.3440388 | E11: 0.13197823 | F11: 11.531061 | G11: 2.4394586 | H11: 0.10791005
A12: 2 | B12: 5.1248232 | C12: 0.12055115 | D12: 2.1064919 | E12: 0.051857133 | F12: 8.264697 | G12: 2.1105152 | H12: 0.054977206
A13: 2.25 | B13: 4.5439268 | C13: 0.086123262 | D13: 2.4802769 | E13: 0.1405129 | F13: 12.41803 | G13: 2.5101047 | H13: 0.14219172
A14: 2.5 | B14: 3.8264962 | C14: 0.084263427 | D14: 2.6188589 | E14: 0.16929819 | F14: 13.998333 | G14: 2.6275897 | H14: 0.16698537
A15: 2.75 | B15: 3.5124937 | C15: 0.096014987 | D15: 2.5527535 | E15: 0.18417748 | F15: 15.416061 | G15: 2.7268151 | H15: 0.13429681
A16: 3 | B16: 3.2134659 | C16: 0.091468395 | D16: 2.4554901 | E16: 0.22082062 | F16: 12.191212 | G16: 2.482599 | H16: 0.19907981
... A99: 23.75 | B99: 24.700385 | C99: 0.31611434 | D99: 3.1654361 | E99: 0.024271341 | F99: 23.762121 | G99: 3.1678047 | H99: 0.024500876
A100: 24 | B100: 21.788138 | C100: 0.24368482 | D100: #NUM! | E100: #NUM! | F100: 21.889697 | G100: 3.085523 | H100: 0.032175155
A101: Grand Total | B101: 24.805438 | C101: 14.076122 | D101: #NUM! | E101: #NUM! | F101: 28.538007 | G101: 3.1892152 | H101: 0.65399187
A106: Row Labels | B106: Average of EPS/core | C106: StdDev of EPS/core2 | D106: Average of AvgOfLogs | E106: StdDev of AvgOfLogs2 | F106: Average of LogOfAvg | G106: StdDev of LogOfAvg
A107: 4.5 | B107: 2.5048359 | C107: 0.093153877 | D107: 1.5805976 | E107: 0.03555241 | F107: 1.5830722 | G107: 0.036064346
A108: 4 | B108: 2.5529545 | C108: 0.067588088 | D108: 1.6143943 | E108: 0.043727203 | F108: 1.6188267 | G108: 0.045904502
A109: 4.75 | B109: 2.5681944 | C109: 0.077383923 | D109: 1.5321352 | E109: 0.031635948 | F109: 1.5362173 | G109: 0.031959954
A110: 4.25 | B110: 2.6317992 | C110: 0.063368952 | D110: 1.5437297 | E110: 0.068052039 | F110: 1.5458439 | G110: 0.068765132
A111: 3.75 | B111: 2.6534912 | C111: 0.076107047 | D111: 1.7233585 | E111: 0.20928113 | F111: 1.7619733 | G111: 0.24785428
A112: 5 | B112: 2.7503788 | C112: 0.090104057 | D112: 1.6567461 | E112: 0.051002332 | F112: 1.663798 | G112: 0.054891514
A113: 3.5 | B113: 2.8181439 | C113: 0.08137587 | D113: 2.4714149 | E113: 0.23279974 | F113: 2.4834175 | G113: 0.2297942
A114: 3.25 | B114: 3.0002588 | C114: 0.091026618 | D114: 2.2973163 | E114: 0.28055547 | F114: 2.3545626 | G114: 0.25381373
A115: 5.25 | B115: 3.0957071 | C115: 0.10042369 | D115: 1.6961048 | E115: 0.071904857 | F115: 1.7006628 | G115: 0.072068996
A116: 3 | B116: 3.2134659 | C116: 0.091468395 | D116: 2.4554901 | E116: 0.22082062 | F116: 2.482599 | G116: 0.19907981
A117: 2.75 | B117: 3.5124937 | C117: 0.096014987 | D117: 2.5527535 | E117: 0.18417748 | F117: 2.7268151 | G117: 0.13429681
A118: 5.5 | B118: 3.5519886 | C118: 0.095117171 | D118: 1.818828 | E118: 0.037381585 | F118: 1.8228641 | G118: 0.037060575
... A138: 8 | B138: 20.678497 | C138: 0.15735555 | D138: 3.2666695 | E138: 0.022660888 | F138: 3.2672327 | G138: 0.022700706
A139: 24 | B139: 21.788138 | C139: 0.24368482 | D139: #NUM! | E139: #NUM! | F139: 3.085523 | G139: 0.032175155
A140: 8.25 | B140: 22.042279 | C140: 0.1730848 | D140: 3.2780477 | E140: 0.02421312 | F140: 3.2794297 | G140: 0.024328031
A141: 8.5 | B141: 23.161641 | C141: 0.18352307 | D141: 3.3147379 | E141: 0.020634933 | F141: 3.3151444 | G141: 0.020566482
A142: 8.75 | B142: 24.564514 | C142: 0.18446602 | D142: 3.3435516 | E142: 0.022878983 | F142: 3.343886 | G142: 0.022789187
A143: 23.75 | B143: 24.700385 | C143: 0.31611434 | D143: 3.1654361 | E143: 0.024271341 | F143: 3.1678047 | G143: 0.024500876
A144: 9 | B144: 25.349691 | C144: 0.20842789 | D144: 3.3814822 | E144: 0.021246996 | F144: 3.3818616 | G144: 0.021140913
A145: 9.25 | B145: 26.084943 | C145: 0.1922128 | D145: 3.3974673 | E145: 0.023236522 | F145: 3.3985329 | G145: 0.023533369
A146: 9.5 | B146: 27.186616 | C146: 0.19964808 | D146: 3.4315309 | E146: 0.023401571 | F146: 3.4319358 | G146: 0.023457097
A147: 9.75 | B147: 27.791357 | C147: 0.24912613 | D147: 3.4627728 | E147: 0.026562175 | F147: 3.4632539 | G147: 0.026546633
...

Sheet MKS all data
A1: SERVER_NAME | B1: hour (rounded to 15 min) | C1: Events total (15 min) | D1: EPS/core | E1: 1 | F1: 2 | G1: 3 | H1: CPU average (15 min) | I1: LogOfAvg | J1: AvgOfLogs
A2: ocsrbmkpapp18 | B2: 4.5 | C2: 16989 | D2: =C2/15/60/8 -> 2.3595833 | E2: 4.85 | F2: 4.44 | G2: 4.94 | H2: =AVERAGE(E2:G2) -> 4.7433333 | I2: =LN(H2) -> 1.5567401 | J2: =(LN(E2)+LN(F2)+LN(G2))/3 -> 1.5556661
A3: ocsrbmkpapp10 | B3: 4.5 | C3: 17076 | D3: =C3/15/60/8 -> 2.3716667 | E3: 5.32 | F3: 4.41 | G3: 4.44 | H3: =AVERAGE(E3:G3) -> 4.7233333 | I3: =LN(H3) -> 1.5525148 | J3: =(LN(E3)+LN(F3)+LN(G3))/3 -> 1.5486675
A4: ocsrbmkpapp5 | B4: 4.5 | C4: 17161 | D4: =C4/15/60/8 -> 2.3834722 | E4: 5.44 | F4: 4.94 | G4: 4.6 | H4: =AVERAGE(E4:G4) -> 4.9933333 | I4: =LN(H4) -> 1.6081037 | J4: =(LN(E4)+LN(F4)+LN(G4))/3 -> 1.6057336
A5: ocsrbmkpapp8 | B5: 4.5 | C5: 17368 | D5: =C5/15/60/8 -> 2.4122222 | E5: 4.69 | F5: 5.42 | G5: 4.81 | H5: =AVERAGE(E5:G5) -> 4.9733333 | I5: =LN(H5) -> 1.6040903 | J5: =(LN(E5)+LN(F5)+LN(G5))/3 -> 1.6020752
A6: ocsrbmkpapp8 | B6: 4.75 | C6: 17452 | D6: =C6/15/60/8 -> 2.4238889 | E6: 3.98 | F6: 5.39 | G6: 4.69 | H6: =AVERAGE(E6:G6) -> 4.6866667 | I6: =LN(H6) -> 1.5447216 | J6: =(LN(E6)+LN(F6)+LN(G6))/3 -> 1.5370866
A7: ocsrbmkpapp3 | B7: 4.5 | C7: 17484 | D7: =C7/15/60/8 -> 2.4283333 | E7: 5.15 | F7: 4.36 | G7: 5.59 | H7: =AVERAGE(E7:G7) -> 5.0333333 | I7: =LN(H7) -> 1.6160825 | J7: =(LN(E7)+LN(F7)+LN(G7))/3 -> 1.610816
A8: ocsrbmkpapp8 | B8: 4 | C8: 17538 | D8: =C8/15/60/8 -> 2.4358333 | E8: 4.96 | F8: 5.48 | G8: 5.1 | H8: =AVERAGE(E8:G8) -> 5.18 | I8: =LN(H8) -> 1.6448051 | J8: =(LN(E8)+LN(F8)+LN(G8))/3 -> 1.6439171
A9: ocsrbmkpapp5 | B9: 4.75 | C9: 17551 | D9: =C9/15/60/8 -> 2.4376389 | E9: 4.04 | F9: 4.56 | G9: 5.02 | H9: =AVERAGE(E9:G9) -> 4.54 | I9: =LN(H9) -> 1.512927 | J9: =(LN(E9)+LN(F9)+LN(G9))/3 -> 1.5089991
A10: ocsrbmkpapp1 | B10: 4.5 | C10: 17582 | D10: =C10/15/60/8 -> 2.4419444 | E10: 4.98 | F10: 5.07 | G10: 4.8 | H10: =AVERAGE(E10:G10) -> 4.95 | I10: =LN(H10) -> 1.5993876 | J10: =(LN(E10)+LN(F10)+LN(G10))/3 -> 1.5991289
A11: ocsrbmkpapp13 | B11: 4.5 | C11: 17641 | D11: =C11/15/60/8 -> 2.4501389 | E11: 5.08 | F11: 5.04 | G11: 4.67 | H11: =AVERAGE(E11:G11) -> 4.93 | I11: =LN(H11) -> 1.595339 | J11: =(LN(E11)+LN(F11)+LN(G11))/3 -> 1.5946255
A12: ocsrbmkpapp7 | B12: 4 | C12: 17657 | D12: =C12/15/60/8 -> 2.4523611 | E12: 5.24 | F12: 4.92 | G12: 4.67 | H12: =AVERAGE(E12:G12) -> 4.9433333 | I12: =LN(H12) -> 1.5980399 | J12: =(LN(E12)+LN(F12)+LN(G12))/3 -> 1.5969297
A13: ocsrbmkpapp2 | B13: 4.5 | C13: 17715 | D13: =C13/15/60/8 -> 2.4604167 | E13: 5.05 | F13: 4.3 | G13: 4.69 | H13: =AVERAGE(E13:G13) -> 4.68 | I13: =LN(H13) -> 1.5432981 | J13: =(LN(E13)+LN(F13)+LN(G13))/3 -> 1.5411453
... A706: ocsrbmkpapp1 | B706: 24 | C706: 153286 | D706: =C706/15/60/8 -> 21.289722 | E706: 21.83 | F706: 21.73 | G706: 21.73 | H706: =AVERAGE(E706:G706) -> 21.763333 | I706: =LN(H706) -> 3.0802266 | J706: =(LN(E706)+LN(F706)+LN(G706))/3 -> 3.0802243
A707: ocsrbmkpapp14 | B707: 24 | C707: 154468 | D707: =C707/15/60/8 -> 21.453889 | E707: 23.16 | F707: 20.76 | H707: =AVERAGE(E707:G707) -> 21.96 | I707: =LN(H707) -> 3.0892226 | J707: =(LN(E707)+LN(F707)+LN(G707))/3 -> #NUM!
A708: ocsrbmkpapp20 | B708: 24 | C708: 155217 | D708: =C708/15/60/8 -> 21.557917 | E708: 23.44 | F708: 21.91 | H708: =AVERAGE(E708:G708) -> 22.675 | I708: =LN(H708) -> 3.121263 | J708: =(LN(E708)+LN(F708)+LN(G708))/3 -> #NUM!
A709: ocsrbmkpapp22 | B709: 24 | C709: 155288 | D709: =C709/15/60/8 -> 21.567778 | E709: 22.76 | F709: 20.99 | H709: =AVERAGE(E709:G709) -> 21.875 | I709: =LN(H709) -> 3.0853444 | J709: =(LN(E709)+LN(F709)+LN(G709))/3 -> #NUM!
A710: ocsrbmkpapp3 | B710: 24 | C710: 155504 | D710: =C710/15/60/8 -> 21.597778 | E710: 21.48 | F710: 20.64 | H710: =AVERAGE(E710:G710) -> 21.06 | I710: =LN(H710) -> 3.0473755 | J710: =(LN(E710)+LN(F710)+LN(G710))/3 -> #NUM!
A711: ocsrbmkpapp1 | B711: 8.25 | C711: 156072 | D711: =C711/15/60/8 -> 21.676667 | E711: 25.77 | F711: 25.16 | G711: 27.09 | H711: =AVERAGE(E711:G711) -> 26.006667 | I711: =LN(H711) -> 3.2583529 | J711: =(LN(E711)+LN(F711)+LN(G711))/3 -> 3.257877
A712: ocsrbmkpapp10 | B712: 24 | C712: 156095 | D712: =C712/15/60/8 -> 21.679861 | E712: 22.33 | F712: 20.41 | H712: =AVERAGE(E712:G712) -> 21.37 | I712: =LN(H712) -> 3.0619881 | J712: =(LN(E712)+LN(F712)+LN(G712))/3 -> #NUM!
A713: ocsrbmkpapp11 | B713: 24 | C713: 156273 | D713: =C713/15/60/8 -> 21.704583 | E713: 20.94 | F713: 19.66 | H713: =AVERAGE(E713:G713) -> 20.3 | I713: =LN(H713) -> 3.0106209 | J713: =(LN(E713)+LN(F713)+LN(G713))/3 -> #NUM!
A714: ocsrbmkpapp2 | B714: 24 | C714: 156319 | D714: =C714/15/60/8 -> 21.710972 | E714: 21.16 | F714: 21.66 | H714: =AVERAGE(E714:G714) -> 21.41 | I714: =LN(H714) -> 3.0638581 | J714: =(LN(E714)+LN(F714)+LN(G714))/3 -> #NUM!
A715: ocsrbmkpapp17 | B715: 24 | C715: 156345 | D715: =C715/15/60/8 -> 21.714583 | E715: 23.13 | F715: 21.23 | H715: =AVERAGE(E715:G715) -> 22.18 | I715: =LN(H715) -> 3.099191 | J715: =(LN(E715)+LN(F715)+LN(G715))/3 -> #NUM!
A716: ocsrbmkpapp6 | B716: 24 | C716: 156372 | D716: =C716/15/60/8 -> 21.718333 | E716: 21.69 | F716: 20.4 | H716: =AVERAGE(E716:G716) -> 21.045 | I716: =LN(H716) -> 3.046663 | J716: =(LN(E716)+LN(F716)+LN(G716))/3 -> #NUM!
A717: ocsrbmkpapp13 | B717: 24 | C717: 156374 | D717: =C717/15/60/8 -> 21.718611 | E717: 22.45 | F717: 21.11 | H717: =AVERAGE(E717:G717) -> 21.78 | I717: =LN(H717) -> 3.0809921 | J717: =(LN(E717)+LN(F717)+LN(G717))/3 -> #NUM!
A718: ocsrbmkpapp16 | B718: 24 | C718: 156434 | D718: =C718/15/60/8 -> 21.726944 | E718: 23.79 | F718: 21.79 | H718: =AVERAGE(E718:G718) -> 22.79 | I718: =LN(H718) -> 3.1263218 | J718: =(LN(E718)+LN(F718)+LN(G718))/3 -> #NUM!
A719: ocsrbmkpapp19 | B719: 24 | C719: 156698 | D719: =C719/15/60/8 -> 21.763611 | E719: 24.48 | F719: 20.92 | H719: =AVERAGE(E719:G719) -> 22.7 | I719: =LN(H719) -> 3.1223649 | J719: =(LN(E719)+LN(F719)+LN(G719))/3 -> #NUM!
A720: ocsrbmkpapp8 | B720: 24 | C720: 156846 | D720: =C720/15/60/8 -> 21.784167 | E720: 23.37 | F720: 23.28 | H720: =AVERAGE(E720:G720) -> 23.325 | I720: =LN(H720) -> 3.1495257 | J720: =(LN(E720)+LN(F720)+LN(G720))/3 -> #NUM!
A721: ocsrbmkpapp14 | B721: 8.25 | C721: 156915 | D721: =C721/15/60/8 -> 21.79375 | E721: 29.78 | F721: 25.13 | G721: 27.92 | H721: =AVERAGE(E721:G721) -> 27.61 | I721: =LN(H721) -> 3.318178 | J721: =(LN(E721)+LN(F721)+LN(G721))/3 -> 3.3157476
A722: ocsrbmkpapp18 | B722: 8.25 | C722: 157121 | D722: =C722/15/60/8 -> 21.822361 | E722: 26.44 | F722: 24.91 | G722: 27.77 | H722: =AVERAGE(E722:G722) -> 26.373333 | I722: =LN(H722) -> 3.2723534 | J722: =(LN(E722)+LN(F722)+LN(G722))/3 -> 3.2713679
A723: ocsrbmkpapp15 | B723: 24 | C723: 157314 | D723: =C723/15/60/8 -> 21.849167 | E723: 23.08 | F723: 20.56 | H723: =AVERAGE(E723:G723) -> 21.82 | I723: =LN(H723) -> 3.082827 | J723: =(LN(E723)+LN(F723)+LN(G723))/3 -> #NUM!
A724: ocsrbmkpapp5 | B724: 8.25 | C724: 157630 | D724: =C724/15/60/8 -> 21.893056 | E724: 27.69 | F724: 24.84 | G724: 27.07 | H724: =AVERAGE(E724:G724) -> 26.533333 | I724: =LN(H724) -> 3.2784018 | J724: =(LN(E724)+LN(F724)+LN(G724))/3 -> 3.2773176
A725: ocsrbmkpapp16 | B725: 8.25 | C725: 157896 | D725: =C725/15/60/8 -> 21.93 | E725: 29.47 | F725: 26.76 | G725: 27.3 | H725: =AVERAGE(E725:G725) -> 27.843333 | I725: =LN(H725) -> 3.3265936 | J725: =(LN(E725)+LN(F725)+LN(G725))/3 -> 3.3257226
A726: ocsrbmkpapp4 | B726: 24 | C726: 158063 | D726: =C726/15/60/8 -> 21.953194 | E726: 22.69 | F726: 22.51 | H726: =AVERAGE(E726:G726) -> 22.6 | I726: =LN(H726) -> 3.1179499 | J726: =(LN(E726)+LN(F726)+LN(G726))/3 -> #NUM!
A727: ocsrbmkpapp9 | B727: 24 | C727: 158118 | D727: =C727/15/60/8 -> 21.960833 | E727: 21.72 | F727: 21.02 | H727: =AVERAGE(E727:G727) -> 21.37 | I727: =LN(H727) -> 3.0619881 | J727: =(LN(E727)+LN(F727)+LN(G727))/3 -> #NUM!
A728: ocsrbmkpapp13 | B728: 8.25 | C728: 158156 | D728: =C728/15/60/8 -> 21.966111 | E728: 28.65 | F728: 24.98 | G728: 26.08 | H728: =AVERAGE(E728:G728) -> 26.57 | I728: =LN(H728) -> 3.2797828 | J728: =(LN(E728)+LN(F728)+LN(G728))/3 -> 3.2781326
A729: ocsrbmkpapp20 | B729: 8.25 | C729: 158271 | D729: =C729/15/60/8 -> 21.982083 | E729: 27.83 | F729: 24.72 | G729: 26.47 | H729: =AVERAGE(E729:G729) -> 26.34 | I729: =LN(H729) -> 3.2710887 | J729: =(LN(E729)+LN(F729)+LN(G729))/3 -> 3.2699131
A730: ocsrbmkpapp15 | B730: 8.25 | C730: 158305 | D730: =C730/15/60/8 -> 21.986806 | E730: 28.09 | F730: 24.67 | G730: 29.2 | H730: =AVERAGE(E730:G730) -> 27.32 | I730: =LN(H730) -> 3.307619 | J730: =(LN(E730)+LN(F730)+LN(G730))/3 -> 3.3050568
A731: ocsrbmkpapp12 | B731: 24 | C731: 158310 | D731: =C731/15/60/8 -> 21.9875 | E731: 22.1 | F731: 20.15 | H731: =AVERAGE(E731:G731) -> 21.125 | I731: =LN(H731) -> 3.0504572 | J731: =(LN(E731)+LN(F731)+LN(G731))/3 -> #NUM!
A732: ocsrbmkpapp18 | B732: 24 | C732: 158397 | D732: =C732/15/60/8 -> 21.999583 | E732: 24.39 | F732: 20.01 | H732: =AVERAGE(E732:G732) -> 22.2 | I732: =LN(H732) -> 3.1000923 | J732: =(LN(E732)+LN(F732)+LN(G732))/3 -> #NUM!
...

Sheet TBS Pivot
A3: Row Labels | B3: Average of Avg CPU
A4: 0.25 | B4: 12.077576
A5: 0.5 | B5: 40.077576
A6: 0.75 | B6: 11.273333
A7: 1 | B7: 9.9207576
A8: 1.25 | B8: 9.4313636
A9: 1.5 | B9: 9.8733333
A10: 1.75 | B10: 6.0290909
A11: 2 | B11: 5.4721212
A12: 2.25 | B12: 5.0342424
A13: 2.5 | B13: 4.7793939
A14: 2.75 | B14: 4.504697
A15: 3 | B15: 4.5951515
... A99: 24 | B99: 10.935952
A100: Grand Total | B100: 22.821825

Sheet TBS all data
E3: Average of CPU in 5 min
A4: HOST_NAME | B4: hour (rounded to 15 min) | C4: Sum of Sum of TOTAL_MSG_NUMBER | D4: EPS/core (avg over 15 min) | E4: CPU 1 | F4: CPU 2 | G4: CPU 3 | H4: Avg CPU
A5: rbs-siapp01 | B5: 0.25 | C5: 48008 | D5: =C5/15/60/8 -> 6.6677778 | E5: 7.91 | F5: 15.35 | G5: 18.77 | H5: =AVERAGE(E5:G5) -> 14.01
A6: rbs-siapp01 | B6: 0.5 | C6: 37778 | D6: =C6/15/60/8 -> 5.2469444 | E6: 55.18 | F6: 38.33 | G6: 20.03 | H6: =AVERAGE(E6:G6) -> 37.846667
A7: rbs-siapp01 | B7: 0.75 | C7: 34260 | D7: =C7/15/60/8 -> 4.7583333 | E7: 14.87 | F7: 6.01 | G7: 8.11 | H7: =AVERAGE(E7:G7) -> 9.6633333
A8: rbs-siapp01 | B8: 1 | C8: 29367 | D8: =C8/15/60/8 -> 4.07875 | E8: 8.16 | F8: 13.05 | G8: 6.67 | H8: =AVERAGE(E8:G8) -> 9.2933333
A9: rbs-siapp01 | B9: 1.25 | C9: 26022 | D9: =C9/15/60/8 -> 3.6141667 | E9: 6.14 | F9: 14.28 | G9: 15.41 | H9: =AVERAGE(E9:G9) -> 11.943333
A10: rbs-siapp01 | B10: 1.5 | C10: 21397 | D10: =C10/15/60/8 -> 2.9718056 | E10: 13.66 | F10: 11.57 | G10: 5.55 | H10: =AVERAGE(E10:G10) -> 10.26
A11: rbs-siapp01 | B11: 1.75 | C11: 20438 | D11: =C11/15/60/8 -> 2.8386111 | E11: 5.13 | F11: 4.76 | G11: 5.87 | H11: =AVERAGE(E11:G11) -> 5.2533333
A12: rbs-siapp01 | B12: 2 | C12: 18275 | D12: =C12/15/60/8 -> 2.5381944 | E12: 5.23 | F12: 4.42 | G12: 5.43 | H12: =AVERAGE(E12:G12) -> 5.0266667
A13: rbs-siapp01 | B13: 2.25 | C13: 18042 | D13: =C13/15/60/8 -> 2.5058333 | E13: 5.31 | F13: 4.8 | G13: 5.45 | H13: =AVERAGE(E13:G13) -> 5.1866667
A14: rbs-siapp01 | B14: 2.5 | C14: 16430 | D14: =C14/15/60/8 -> 2.2819444 | E14: 4.73 | F14: 4.26 | G14: 4.92 | H14: =AVERAGE(E14:G14) -> 4.6366667
A15: rbs-siapp01 | B15: 2.75 | C15: 15824 | D15: =C15/15/60/8 -> 2.1977778 | E15: 4.41 | F15: 4.31 | G15: 5.12 | H15: =AVERAGE(E15:G15) -> 4.6133333
A16: rbs-siapp01 | B16: 3 | C16: 14921 | D16: =C16/15/60/8 -> 2.0723611 | E16: 4.08 | F16: 4.3 | G16: 4.89 | H16: =AVERAGE(E16:G16) -> 4.4233333
... A99: rbs-siapp13 | B99: 6.5 | C99: 91912 | D99: =C99/15/60/8 -> 12.765556 | E99: 15.48 | F99: 16.51 | G99: 17.69 | H99: =AVERAGE(E99:G99) -> 16.56
A100: rbs-siapp01 | B100: 24 | C100: 65585 | D100: =C100/15/60/8 -> 9.1090278 | E100: 10.76 | F100: 9.74 | H100: =AVERAGE(E100:G100) -> 10.25
A101: rbs-siapp02 | B101: 0.25 | C101: 48402 | D101: =C101/15/60/8 -> 6.7225 | E101: 8.17 | F101: 16.45 | G101: 19.01 | H101: =AVERAGE(E101:G101) -> 14.543333
A102: rbs-siapp02 | B102: 0.5 | C102: 37598 | D102: =C102/15/60/8 -> 5.2219444 | E102: 55.31 | F102: 34.63 | G102: 31.58 | H102: =AVERAGE(E102:G102) -> 40.506667
A103: rbs-siapp02 | B103: 0.75 | C103: 32929 | D103: =C103/15/60/8 -> 4.5734722 | E103: 20.39 | F103: 6.87 | G103: 5.9 | H103: =AVERAGE(E103:G103) -> 11.053333
A104: rbs-siapp02 | B104: 1 | C104: 28744 | D104: =C104/15/60/8 -> 3.9922222 | E104: 9.51 | F104: 13.07 | G104: 7.04 | H104: =AVERAGE(E104:G104) -> 9.8733333
A105: rbs-siapp02 | B105: 1.25 | C105: 25986 | D105: =C105/15/60/8 -> 3.6091667 | E105: 5.83 | F105: 14.91 | G105: 15.37 | H105: =AVERAGE(E105:G105) -> 12.036667
A106: rbs-siapp02 | B106: 1.5 | C106: 21330 | D106: =C106/15/60/8 -> 2.9625 | E106: 14.19 | F106: 5.28 | G106: 5.97 | H106: =AVERAGE(E106:G106) -> 8.48
A107: rbs-siapp02 | B107: 1.75 | C107: 20280 | D107: =C107/15/60/8 -> 2.8166667 | E107: 4.9 | F107: 4.69 | G107: 5.28 | H107: =AVERAGE(E107:G107) -> 4.9566667
A108: rbs-siapp02 | B108: 2 | C108: 18441 | D108: =C108/15/60/8 -> 2.56125 | E108: 5.01 | F108: 4.88 | G108: 5.63 | H108: =AVERAGE(E108:G108) -> 5.1733333
A109: rbs-siapp02 | B109: 2.25 | C109: 17888 | D109: =C109/15/60/8 -> 2.4844444 | E109: 5.15 | F109: 4.52 | G109: 5.01 | H109: =AVERAGE(E109:G109) -> 4.8933333
A110: rbs-siapp02 | B110: 2.5 | C110: 15901 | D110: =C110/15/60/8 -> 2.2084722 | E110: 4.55 | F110: 4.55 | G110: 5.12 | H110: =AVERAGE(E110:G110) -> 4.74
A111: rbs-siapp02 | B111: 2.75 | C111: 15285 | D111: =C111/15/60/8 -> 2.1229167 | E111: 4.26 | F111: 4.02 | G111: 4.3 | H111: =AVERAGE(E111:G111) -> 4.1933333
A112: rbs-siapp02 | B112: 3 | C112: 14178 | D112: =C112/15/60/8 -> 1.9691667 | E112: 3.88 | F112: 4.6 | G112: 5.06 | H112: =AVERAGE(E112:G112) -> 4.5133333
... A195: rbs-siapp13 | B195: 7 | C195: 111129 | D195: =C195/15/60/8 -> 15.434583 | E195: 18.18 | F195: 18.92 | G195: 20.62 | H195: =AVERAGE(E195:G195) -> 19.24
A196: rbs-siapp02 | B196: 24 | C196: 66291 | D196: =C196/15/60/8 -> 9.2070833 | E196: 10.47 | F196: 10.42 | H196: =AVERAGE(E196:G196) -> 10.445
A197: rbs-siapp03 | B197: 0.25 | C197: 48862 | D197: =C197/15/60/8 -> 6.7863889 | E197: 8.19 | F197: 13.27 | G197: 18.57 | H197: =AVERAGE(E197:G197) -> 13.343333
A198: rbs-siapp03 | B198: 0.5 | C198: 37974 | D198: =C198/15/60/8 -> 5.2741667 | E198: 53.9 | F198: 38.15 | G198: 38.56 | H198: =AVERAGE(E198:G198) -> 43.536667
A199: rbs-siapp03 | B199: 0.75 | C199: 34017 | D199: =C199/15/60/8 -> 4.7245833 | E199: 22.27 | F199: 7.58 | G199: 7.15 | H199: =AVERAGE(E199:G199) -> 12.333333
A200: rbs-siapp03 | B200: 1 | C200: 28794 | D200: =C200/15/60/8 -> 3.9991667 | E200: 11.65 | F200: 14.55 | G200: 7.19 | H200: =AVERAGE(E200:G200) -> 11.13
A201: rbs-siapp03 | B201: 1.25 | C201: 26811 | D201: =C201/15/60/8 -> 3.72375 | E201: 6.71 | F201: 12.18 | G201: 16.22 | H201: =AVERAGE(E201:G201) -> 11.703333
A202: rbs-siapp03 | B202: 1.5 | C202: 21511 | D202: =C202/15/60/8 -> 2.9876389 | E202: 14.62 | F202: 13.27 | G202: 6.51 | H202: =AVERAGE(E202:G202) -> 11.466667
A203: rbs-siapp03 | B203: 1.75 | C203: 19689 | D203: =C203/15/60/8 -> 2.7345833 | E203: 5 | F203: 4.55 | G203: 5.88 | H203: =AVERAGE(E203:G203) -> 5.1433333
A204: rbs-siapp03 | B204: 2 | C204: 18113 | D204: =C204/15/60/8 -> 2.5156944 | E204: 5.84 | F204: 4.77 | G204: 5.2 | H204: =AVERAGE(E204:G204) -> 5.27
A205: rbs-siapp03 | B205: 2.25 | C205: 17258 | D205: =C205/15/60/8 -> 2.3969444 | E205: 5.44 | F205: 4.39 | G205: 5.44 | H205: =AVERAGE(E205:G205) -> 5.09
A206: rbs-siapp03 | B206: 2.5 | C206: 16057 | D206: =C206/15/60/8 -> 2.2301389 | E206: 5.32 | F206: 4.16 | G206: 4.76 | H206: =AVERAGE(E206:G206) -> 4.7466667
...

Sheet MKS filtered data
A1: SERVER_NAME | B1: hour (rounded to 15 min) | C1: Events total (15 min) | D1: EPS/core | E1: CPU avg in 15 min | F1: 1 | G1: 2 | H1: 3 | I1: filter
A2: ocsrbmkpapp1 | B2: 7.25 | C2: 106373 | D2: =C2/15/60/8 -> 14.774028 | E2: =AVERAGE(F2:H2) -> 18.393333 | F2: 16.61 | G2: 18.66 | H2: 19.91 | I2: =G2/F2>2 -> FALSE
A3: ocsrbmkpapp1 | B3: 0.5 | C3: 91818 | D3: =C3/15/60/8 -> 12.7525 | F3: 42.6 | G3: 41.13 | H3: 43.95 | I3: =AVERAGE(F3:H3) -> 42.56
A4: ocsrbmkpapp1 | B4: 0.75 | C4: 74338 | D4: =C4/15/60/8 -> 10.324722 | F4: 26.95 | G4: 15.62 | H4: 13.77 | I4: =AVERAGE(F4:H4) -> 18.78
A5: ocsrbmkpapp1 | B5: 1 | C5: 60977 | D5: =C5/15/60/8 -> 8.4690278 | F5: 20.76 | G5: 11.69 | H5: 13.73 | I5: =AVERAGE(F5:H5) -> 15.393333
A6: ocsrbmkpapp1 | B6: 1.25 | C6: 57565 | D6: =C6/15/60/8 -> 7.9951389 | F6: 8.89 | G6: 8.55 | H6: 16.94 | I6: =AVERAGE(F6:H6) -> 11.46
A7: ocsrbmkpapp1 | B7: 1.5 | C7: 46488 | D7: =C7/15/60/8 -> 6.4566667 | F7: 15.83 | G7: 14.99 | H7: 17.01 | I7: =AVERAGE(F7:H7) -> 15.943333
A8: ocsrbmkpapp1 | B8: 1.75 | C8: 41930 | D8: =C8/15/60/8 -> 5.8236111 | F8: 12.47 | G8: 6.34 | H8: 18.19 | I8: =AVERAGE(F8:H8) -> 12.333333
A9: ocsrbmkpapp17 | B9: 7.25 | C9: 107126 | D9: =C9/15/60/8 -> 14.878611 | E9: =AVERAGE(F9:H9) -> 18.623333 | F9: 17.54 | G9: 19.57 | H9: 18.76 | I9: =G9/F9>2 -> FALSE
A10: ocsrbmkpapp22 | B10: 7.25 | C10: 107693 | D10: =C10/15/60/8 -> 14.957361 | E10: =AVERAGE(F10:H10) -> 18.073333 | F10: 17.28 | G10: 18.08 | H10: 18.86 | I10: =G10/F10>2 -> FALSE
A11: ocsrbmkpapp21 | B11: 7.25 | C11: 108152 | D11: =C11/15/60/8 -> 15.021111 | E11: =AVERAGE(F11:H11) -> 17.743333 | F11: 16.74 | G11: 18.73 | H11: 17.76 | I11: =G11/F11>2 -> FALSE
A12: ocsrbmkpapp16 | B12: 7.25 | C12: 108259 | D12: =C12/15/60/8 -> 15.035972 | E12: =AVERAGE(F12:H12) -> 18.883333 | F12: 17.71 | G12: 18.97 | H12: 19.97 | I12: =G12/F12>2 -> FALSE
A13: ocsrbmkpapp11 | B13: 7.25 | C13: 108517 | D13: =C13/15/60/8 -> 15.071806 | E13: =AVERAGE(F13:H13) -> 18.533333 | F13: 16.71 | G13: 18.67 | H13: 20.22 | I13: =G13/F13>2 -> FALSE
A14: ocsrbmkpapp18 | B14: 7.25 | C14: 108885 | D14: =C14/15/60/8 -> 15.122917 | E14: =AVERAGE(F14:H14) -> 18.18 | F14: 16.76 | G14: 17.91 | H14: 19.87 | I14: =G14/F14>2 -> FALSE
A15: ocsrbmkpapp13 | B15: 7.25 | C15: 109205 | D15: =C15/15/60/8 -> 15.167361 | E15: =AVERAGE(F15:H15) -> 18.836667 | F15: 17.17 | G15: 18.04 | H15: 21.3 | I15: =G15/F15>2 -> FALSE
A16: ocsrbmkpapp6 | B16: 7.25 | C16: 109283 | D16: =C16/15/60/8 -> 15.178194 | E16: =AVERAGE(F16:H16) -> 18.37 | F16: 17.1 | G16: 17.78 | H16: 20.23 | I16: =G16/F16>2 -> FALSE
A17: ocsrbmkpapp2 | B17: 7.25 | C17: 109333 | D17: =C17/15/60/8 -> 15.185139 | E17: =AVERAGE(F17:H17) -> 18.19 | F17: 16.41 | G17: 18.54 | H17: 19.62 | I17: =G17/F17>2 -> FALSE
A18: ocsrbmkpapp14 | B18: 7.25 | C18: 109563 | D18: =C18/15/60/8 -> 15.217083 | E18: =AVERAGE(F18:H18) -> 19.11 | F18: 18.24 | G18: 19.08 | H18: 20.01 | I18: =G18/F18>2 -> FALSE
A19: ocsrbmkpapp19 | B19: 7.25 | C19: 109634 | D19: =C19/15/60/8 -> 15.226944 | E19: =AVERAGE(F19:H19) -> 17.976667 | F19: 16.81 | G19: 17.86 | H19: 19.26 | I19: =G19/F19>2 -> FALSE
A20: ocsrbmkpapp10 | B20: 7.25 | C20: 109817 | D20: =C20/15/60/8 -> 15.252361 | E20: =AVERAGE(F20:H20) -> 18.093333 | F20: 17.01 | G20: 17.73 | H20: 19.54 | I20: =G20/F20>2 -> FALSE
... A29: ocsrbmkpapp15 | B29: 7.25 | C29: 111124 | D29: =C29/15/60/8 -> 15.433889 | E29: =AVERAGE(F29:H29) -> 18.746667 | F29: 17.18 | G29: 18.33 | H29: 20.73 | I29: =G29/F29>2 -> FALSE
A30: ocsrbmkpapp16 | B30: 0.25 | C30: 117067 | D30: =C30/15/60/8 -> 16.259306 | F30: 19.25 | G30: 55.71 | H30: 42.24 | I30: =G30/F30>2 -> TRUE
A31: ocsrbmkpapp3 | B31: 0.25 | C31: 117465 | D31: =C31/15/60/8 -> 16.314583 | F31: 16.79 | G31: 48.66 | H31: 35.52 | I31: =G31/F31>2 -> TRUE
A32: ocsrbmkpapp1 | B32: 0.25 | C32: 117601 | D32: =C32/15/60/8 -> 16.333472 | F32: 16.27 | G32: 55.7 | H32: 42.06 | I32: =G32/F32>2 -> TRUE
A33: ocsrbmkpapp13 | B33: 0.25 | C33: 118027 | D33: =C33/15/60/8 -> 16.392639 | F33: 17.45 | G33: 55.95 | H33: 38.19 | I33: =G33/F33>2 -> TRUE
A34: ocsrbmkpapp2 | B34: 0.25 | C34: 118323 | D34: =C34/15/60/8 -> 16.43375 | F34: 16.53 | G34: 56.9 | H34: 43.1 | I34: =G34/F34>2 -> TRUE
A35: ocsrbmkpapp6 | B35: 0.25 | C35: 118755 | D35: =C35/15/60/8 -> 16.49375 | F35: 17.62 | G35: 55.36 | H35: 43.11 | I35: =G35/F35>2 -> TRUE
A36: ocsrbmkpapp5 | B36: 0.25 | C36: 119036 | D36: =C36/15/60/8 -> 16.532778 | F36: 17.61 | G36: 56.22 | H36: 43.87 | I36: =G36/F36>2 -> TRUE
A37: ocsrbmkpapp20 | B37: 0.25 | C37: 119150 | D37: =C37/15/60/8 -> 16.548611 | F37: 17.53 | G37: 58 | H37: 39.3 | I37: =G37/F37>2 -> TRUE
A38: ocsrbmkpapp18 | B38: 0.25 | C38: 119217 | D38: =C38/15/60/8 -> 16.557917 | F38: 18.11 | G38: 57.06 | H38: 42.54 | I38: =G38/F38>2 -> TRUE
A39: ocsrbmkpapp9 | B39: 0.25 | C39: 119595 | D39: =C39/15/60/8 -> 16.610417 | F39: 16.86 | G39: 57.58 | H39: 45.09 | I39: =G39/F39>2 -> TRUE
A40: ocsrbmkpapp17 | B40: 0.25 | C40: 119614 | D40: =C40/15/60/8 -> 16.613056 | F40: 19.43 | G40: 58.91 | H40: 46.58 | I40: =G40/F40>2 -> TRUE
A41: ocsrbmkpapp10 | B41: 0.25 | C41: 119770 | D41: =C41/15/60/8 -> 16.634722 | F41: 16.76 | G41: 55.41 | H41: 40.08 | I41: =G41/F41>2 -> TRUE
... A48: ocsrbmkpapp21 | B48: 0.25 | C48: 120899 | D48: =C48/15/60/8 -> 16.791528 | F48: 17.49 | G48: 61.1 | H48: 45.86 | I48: =G48/F48>2 -> TRUE
A49: ocsrbmkpapp1 | B49: 2 | C49: 35329 | D49: =C49/15/60/8 -> 4.9068056 | F49: 7.83 | G49: 8.47 | H49: 12.08 | I49: =AVERAGE(F49:H49) -> 9.46
A50: ocsrbmkpapp1 | B50: 2.25 | C50: 31484 | D50: =C50/15/60/8 -> 4.3727778 | F50: 16.95 | G50: 12.43 | H50: 17.81 | I50: =AVERAGE(F50:H50) -> 15.73
A51: ocsrbmkpapp1 | B51: 2.5 | C51: 26337 | D51: =C51/15/60/8 -> 3.6579167 | F51: 16.58 | G51: 16.7 | H51: 16.2 | I51: =AVERAGE(F51:H51) -> 16.493333
A52: ocsrbmkpapp1 | B52: 2.75 | C52: 24358 | D52: =C52/15/60/8 -> 3.3830556 | F52: 9.49 | G52: 9.57 | H52: 34.95 | I52: =AVERAGE(F52:H52) -> 18.003333
A53: ocsrbmkpapp14 | B53: 0.25 | C53: 121000 | D53: =C53/15/60/8 -> 16.805556 | F53: 17.1 | G53: 57.4 | H53: 41.5 | I53: =G53/F53>2 -> TRUE
A54: ocsrbmkpapp1 | B54: 7.5 | C54: 121158 | D54: =C54/15/60/8 -> 16.8275 | E54: =AVERAGE(F54:H54) -> 20.693333 | F54: 20.33 | G54: 20.67 | H54: 21.08 | I54: =G54/F54>2 -> FALSE
...

Sheet TBS filtered data
E3: Average of CPU in 5 min
A4: HOST_NAME | B4: hour (rounded to 15 min) | C4: Sum of Sum of TOTAL_MSG_NUMBER | D4: EPS/core (avg over 15 min) | E4: CPU 1 | F4: CPU 2 | G4: CPU 3 | H4: Avg CPU
A5: rbs-siapp01 | B5: 0.25 | C5: 48008 | D5: =C5/15/60/8 -> 6.6677778 | E5: 7.91 | F5: 15.35 | G5: 18.77 | H5: =AVERAGE(E5:G5) -> 14.01
A6: rbs-siapp01 | B6: 0.5 | C6: 37778 | D6: =C6/15/60/8 -> 5.2469444 | E6: 55.18 | F6: 38.33 | G6: 20.03 | H6: =AVERAGE(E6:G6) -> 37.846667
A7: rbs-siapp01 | B7: 0.75 | C7: 34260 | D7: =C7/15/60/8 -> 4.7583333 | E7: 14.87 | F7: 6.01 | G7: 8.11 | H7: =AVERAGE(E7:G7) -> 9.6633333
A8: rbs-siapp01 | B8: 1 | C8: 29367 | D8: =C8/15/60/8 -> 4.07875 | E8: 8.16 | F8: 13.05 | G8: 6.67 | H8: =AVERAGE(E8:G8) -> 9.2933333
A9: rbs-siapp01 | B9: 1.25 | C9: 26022 | D9: =C9/15/60/8 -> 3.6141667 | E9: 6.14 | F9: 14.28 | G9: 15.41 | H9: =AVERAGE(E9:G9) -> 11.943333
A10: rbs-siapp01 | B10: 1.5 | C10: 21397 | D10: =C10/15/60/8 -> 2.9718056 | E10: 13.66 | F10: 11.57 | G10: 5.55 | H10: =AVERAGE(E10:G10) -> 10.26
A11: rbs-siapp01 | B11: 1.75 | C11: 20438 | D11: =C11/15/60/8 -> 2.8386111 | E11: 5.13 | F11: 4.76 | G11: 5.87 | H11: =AVERAGE(E11:G11) -> 5.2533333
A12: rbs-siapp01 | B12: 2 | C12: 18275 | D12: =C12/15/60/8 -> 2.5381944 | E12: 5.23 | F12: 4.42 | G12: 5.43 | H12: =AVERAGE(E12:G12) -> 5.0266667
A13: rbs-siapp01 | B13: 2.25 | C13: 18042 | D13: =C13/15/60/8 -> 2.5058333 | E13: 5.31 | F13: 4.8 | G13: 5.45 | H13: =AVERAGE(E13:G13) -> 5.1866667
A14: rbs-siapp01 | B14: 2.5 | C14: 16430 | D14: =C14/15/60/8 -> 2.2819444 | E14: 4.73 | F14: 4.26 | G14: 4.92 | H14: =AVERAGE(E14:G14) -> 4.6366667
A15: rbs-siapp01 | B15: 2.75 | C15: 15824 | D15: =C15/15/60/8 -> 2.1977778 | E15: 4.41 | F15: 4.31 | G15: 5.12 | H15: =AVERAGE(E15:G15) -> 4.6133333
A16: rbs-siapp01 | B16: 3 | C16: 14921 | D16: =C16/15/60/8 -> 2.0723611 | E16: 4.08 | F16: 4.3 | G16: 4.89 | H16: =AVERAGE(E16:G16) -> 4.4233333
... A99: rbs-siapp01 | B99: 6.5 | C99: 91572 | D99: =C99/15/60/8 -> 12.718333 | E99: 15.31 | F99: 16.1 | G99: 17.28 | H99: =AVERAGE(E99:G99) -> 16.23
A100: rbs-siapp01 | B100: 24 | C100: 65585 | D100: =C100/15/60/8 -> 9.1090278 | E100: 10.76 | F100: 9.74 | H100: =AVERAGE(E100:G100) -> 10.25
A101: rbs-siapp02 | B101: 0.25 | C101: 48402 | D101: =C101/15/60/8 -> 6.7225 | E101: 8.17 | F101: 16.45 | G101: 19.01 | H101: =AVERAGE(E101:G101) -> 14.543333
A102: rbs-siapp02 | B102: 0.5 | C102: 37598 | D102: =C102/15/60/8 -> 5.2219444 | E102: 55.31 | F102: 34.63 | G102: 31.58 | H102: =AVERAGE(E102:G102) -> 40.506667
A103: rbs-siapp02 | B103: 0.75 | C103: 32929 | D103: =C103/15/60/8 -> 4.5734722 | E103: 20.39 | F103: 6.87 | G103: 5.9 | H103: =AVERAGE(E103:G103) -> 11.053333
A104: rbs-siapp02 | B104: 1 | C104: 28744 | D104: =C104/15/60/8 -> 3.9922222 | E104: 9.51 | F104: 13.07 | G104: 7.04 | H104: =AVERAGE(E104:G104) -> 9.8733333
A105: rbs-siapp02 | B105: 1.25 | C105: 25986 | D105: =C105/15/60/8 -> 3.6091667 | E105: 5.83 | F105: 14.91 | G105: 15.37 | H105: =AVERAGE(E105:G105) -> 12.036667
A106: rbs-siapp02 | B106: 1.5 | C106: 21330 | D106: =C106/15/60/8 -> 2.9625 | E106: 14.19 | F106: 5.28 | G106: 5.97 | H106: =AVERAGE(E106:G106) -> 8.48
A107: rbs-siapp02 | B107: 1.75 | C107: 20280 | D107: =C107/15/60/8 -> 2.8166667 | E107: 4.9 | F107: 4.69 | G107: 5.28 | H107: =AVERAGE(E107:G107) -> 4.9566667
A108: rbs-siapp02 | B108: 2 | C108: 18441 | D108: =C108/15/60/8 -> 2.56125 | E108: 5.01 | F108: 4.88 | G108: 5.63 | H108: =AVERAGE(E108:G108) -> 5.1733333
A109: rbs-siapp02 | B109: 2.25 | C109: 17888 | D109: =C109/15/60/8 -> 2.4844444 | E109: 5.15 | F109: 4.52 | G109: 5.01 | H109: =AVERAGE(E109:G109) -> 4.8933333
A110: rbs-siapp02 | B110: 2.5 | C110: 15901 | D110: =C110/15/60/8 -> 2.2084722 | E110: 4.55 | F110: 4.55 | G110: 5.12 | H110: =AVERAGE(E110:G110) -> 4.74
A111: rbs-siapp02 | B111: 2.75 | C111: 15285 | D111: =C111/15/60/8 -> 2.1229167 | E111: 4.26 | F111: 4.02 | G111: 4.3 | H111: =AVERAGE(E111:G111) -> 4.1933333
A112: rbs-siapp02 | B112: 3 | C112: 14178 | D112: =C112/15/60/8 -> 1.9691667 | E112: 3.88 | F112: 4.6 | G112: 5.06 | H112: =AVERAGE(E112:G112) -> 4.5133333
... A195: rbs-siapp18 | B195: 7.25 | C195: 121149 | D195: =C195/15/60/8 -> 16.82625 | E195: 17.43 | F195: 19.14 | G195: 20.45 | H195: =AVERAGE(E195:G195) -> 19.006667
A196: rbs-siapp02 | B196: 24 | C196: 66291 | D196: =C196/15/60/8 -> 9.2070833 | E196: 10.47 | F196: 10.42 | H196: =AVERAGE(E196:G196) -> 10.445
A197: rbs-siapp03 | B197: 0.25 | C197: 48862 | D197: =C197/15/60/8 -> 6.7863889 | E197: 8.19 | F197: 13.27 | G197: 18.57 | H197: =AVERAGE(E197:G197) -> 13.343333
A198: rbs-siapp03 | B198: 0.5 | C198: 37974 | D198: =C198/15/60/8 -> 5.2741667 | E198: 53.9 | F198: 38.15 | G198: 38.56 | H198: =AVERAGE(E198:G198) -> 43.536667
A199: rbs-siapp03 | B199: 0.75 | C199: 34017 | D199: =C199/15/60/8 -> 4.7245833 | E199: 22.27 | F199: 7.58 | G199: 7.15 | H199: =AVERAGE(E199:G199) -> 12.333333
A200: rbs-siapp03 | B200: 1 | C200: 28794 | D200: =C200/15/60/8 -> 3.9991667 | E200: 11.65 | F200: 14.55 | G200: 7.19 | H200: =AVERAGE(E200:G200) -> 11.13
A201: rbs-siapp03 | B201: 1.25 | C201: 26811 | D201: =C201/15/60/8 -> 3.72375 | E201: 6.71 | F201: 12.18 | G201: 16.22 | H201: =AVERAGE(E201:G201) -> 11.703333
A202: rbs-siapp03 | B202: 1.5 | C202: 21511 | D202: =C202/15/60/8 -> 2.9876389 | E202: 14.62 | F202: 13.27 | G202: 6.51 | H202: =AVERAGE(E202:G202) -> 11.466667
A203: rbs-siapp03 | B203: 1.75 | C203: 19689 | D203: =C203/15/60/8 -> 2.7345833 | E203: 5 | F203: 4.55 | G203: 5.88 | H203: =AVERAGE(E203:G203) -> 5.1433333
A204: rbs-siapp03 | B204: 2 | C204: 18113 | D204: =C204/15/60/8 -> 2.5156944 | E204: 5.84 | F204: 4.77 | G204: 5.2 | H204: =AVERAGE(E204:G204) -> 5.27
A205: rbs-siapp03 | B205: 2.25 | C205: 17258 | D205: =C205/15/60/8 -> 2.3969444 | E205: 5.44 | F205: 4.39 | G205: 5.44 | H205: =AVERAGE(E205:G205) -> 5.09
A206: rbs-siapp03 | B206: 2.5 | C206: 16057 | D206: =C206/15/60/8 -> 2.2301389 | E206: 5.32 | F206: 4.16 | G206: 4.76 | H206: =AVERAGE(E206:G206) -> 4.7466667
...

Sheet CG
A1: Site | B1: EPS/core | C1: CPU | D1: LogCPU | E1: EPS Bin
A2: TBS | B2: 7.5430556 | C2: 10.543333 | D2: =LN(C2) -> 2.3554937 | E2: =ROUND(B2,0) -> 8
A3: TBS | B3: 7.6068056 | C3: 11.416667 | D3: =LN(C3) -> 2.4350743 | E3: =ROUND(B3,0) -> 8
A4: TBS | B4: 7.6402778 | C4: 10.973333 | D4: =LN(C4) -> 2.3954681 | E4: =ROUND(B4,0) -> 8
A5: TBS | B5: 7.7154167 | C5: 11.003333 | D5: =LN(C5) -> 2.3981983 | E5: =ROUND(B5,0) -> 8
A6: TBS | B6: 7.7280556 | C6: 11.306667 | D6: =LN(C6) -> 2.4253925 | E6: =ROUND(B6,0) -> 8
A7: TBS | B7: 7.7480556 | C7: 11.023333 | D7: =LN(C7) -> 2.4000142 | E7: =ROUND(B7,0) -> 8
A8: TBS | B8: 7.7929167 | C8: 10.966667 | D8: =LN(C8) -> 2.3948604 | E8: =ROUND(B8,0) -> 8
A9: TBS | B9: 7.7975 | C9: 10.97 | D9: =LN(C9) -> 2.3951643 | E9: =ROUND(B9,0) -> 8
A10: TBS | B10: 7.7991667 | C10: 11.096667 | D10: =LN(C10) -> 2.4066448 | E10: =ROUND(B10,0) -> 8
A11: TBS | B11: 7.8294444 | C11: 10.993333 | D11: =LN(C11) -> 2.397289 | E11: =ROUND(B11,0) -> 8
A12: TBS | B12: 7.8343056 | C12: 10.973333 | D12: =LN(C12) -> 2.3954681 | E12: =ROUND(B12,0) -> 8
A13: TBS | B13: 7.8394444 | C13: 11.16 | D13: =LN(C13) -> 2.412336 | E13: =ROUND(B13,0) -> 8
... A20: TBS | B20: 7.9533333 | C20: 11.62 | D20: =LN(C20) -> 2.4527278 | E20: =ROUND(B20,0) -> 8
A21: TBS | B21: 7.9640278 | C21: 11.38 | D21: =LN(C21) -> 2.4318574 | E21: =ROUND(B21,0) -> 8 | H21: Values
A22: TBS | B22: 7.9666667 | C22: 11.116667 | D22: =LN(C22) -> 2.4084455 | E22: =ROUND(B22,0) -> 8 | G22: Row Labels | H22: Average of LogCPU | I22: StdDevp of LogCPU
A23: TBS | B23: 7.9940278 | C23: 10.803333 | D23: =LN(C23) -> 2.3798547 | E23: =ROUND(B23,0) -> 8 | G23: 8 | H23: 2.4044431 | I23: 0.027260783
A24: TBS | B24: 9.2365278 | C24: 13.016667 | D24: =LN(C24) -> 2.5662306 | E24: =ROUND(B24,0) -> 9 | G24: 9 | H24: 2.5869776 | I24: 0.023820624
A25: TBS | B25: 9.3525 | C25: 13.776667 | D25: =LN(C25) -> 2.6229763 | E25: =ROUND(B25,0) -> 9 | G25: 10 | H25: 2.5579213 | I25: 0.066118596
A26: TBS | B26: 9.3577778 | C26: 13.81 | D26: =LN(C26) -> 2.625393 | E26: =ROUND(B26,0) -> 9 | G26: 11 | H26: 2.5996408 | I26: 0.10727251
A27: TBS | B27: 9.3702778 | C27: 12.91 | D27: =LN(C27) -> 2.5580022 | E27: =ROUND(B27,0) -> 9 | G27: 12 | H27: 2.7009549 | I27: 0.063293178
A28: TBS | B28: 9.3902778 | C28: 13.283333 | D28: =LN(C28) -> 2.5865101 | E28: =ROUND(B28,0) -> 9 | G28: 13 | H28: 2.7280936 | I28: 0.088968167
A29: TBS | B29: 9.4159722 | C29: 13.37 | D29: =LN(C29) -> 2.5930134 | E29: =ROUND(B29,0) -> 9 | G29: 14 | H29: 2.8664699 | I29: 0.024839419
A30: TBS | B30: 9.4441667 | C30: 13.073333 | D30: =LN(C30) -> 2.5705745 | E30: =ROUND(B30,0) -> 9 | G30: 15 | H30: 2.8513514 | I30: 0.099402741
A31: TBS | B31: 9.4880556 | C31: 13.106667 | D31: =LN(C31) -> 2.573121 | E31: =ROUND(B31,0) -> 9 | G31: 16 | H31: 2.9600445 | I31: 0.027881286
A32: TBS | B32: 9.5033333 | C32: 13.333333 | D32: =LN(C32) -> 2.5902672 | E32: =ROUND(B32,0) -> 10 | G32: 17 | H32: 2.9803198 | I32: 0.069456972
A33: TBS | B33: 9.5038889 | C33: 13.15 | D33: =LN(C33) -> 2.5764218 | E33: =ROUND(B33,0) -> 10 | G33: 18 | H33: 3.0325105 | I33: 0.066420773
A34: TBS | B34: 9.5073611 | C34: 14.083333 | D34: =LN(C34) -> 2.6449921 | E34: =ROUND(B34,0) -> 10 | G34: 19 | H34: 3.1140752 | I34: 0.094820939
... A67: TBS | B67: 10.926528 | C67: 12.283333 | D67: =LN(C67) -> 2.5082433 | E67: =ROUND(B67,0) -> 11 | G67: 52 | H67: 3.8871691 | I67: 0.028150059
A68: TBS | B68: 11.0025 | C68: 14.243333 | D68: =LN(C68) -> 2.656289 | E68: =ROUND(B68,0) -> 11 | G68: Grand Total | H68: 3.4011596 | I68: 0.2774664
A69: TBS | B69: 11.037917 | C69: 14.19 | D69: =LN(C69) -> 2.6525375 | E69: =ROUND(B69,0) -> 11
A70: TBS | B70: 11.062222 | C70: 15.046667 | D70: =LN(C70) -> 2.7111565 | E70: =ROUND(B70,0) -> 11
A71: TBS | B71: 11.069861 | C71: 14.476667 | D71: =LN(C71) -> 2.6725382 | E71: =ROUND(B71,0) -> 11
A72: TBS | B72: 11.073333 | C72: 14.403333 | D72: =LN(C72) -> 2.6674597 | E72: =ROUND(B72,0) -> 11
A73: TBS | B73: 11.084444 | C73: 14.206667 | D73: =LN(C73) -> 2.6537113 | E73: =ROUND(B73,0) -> 11
A74: TBS | B74: 11.089722 | C74: 14.676667 | D74: =LN(C74) -> 2.6862589 | E74: =ROUND(B74,0) -> 11
A75: TBS | B75: 11.104028 | C75: 14.526667 | D75: =LN(C75) -> 2.675986 | E75: =ROUND(B75,0) -> 11
A76: TBS | B76: 11.113194 | C76: 14.566667 | D76: =LN(C76) -> 2.6787358 | E76: =ROUND(B76,0) -> 11
A77: TBS | B77: 11.1175 | C77: 14.693333 | D77: =LN(C77) -> 2.6873939 | E77: =ROUND(B77,0) -> 11
A78: TBS | B78: 11.124167 | C78: 14.683333 | D78: =LN(C78) -> 2.6867131 | E78: =ROUND(B78,0) -> 11
...
