Workbook

Sheet QResults
A1: Events Success Ratio (from contract, used to calculate cost of failure)
A2: From | D2: To | E2: Revenue Share | F2: Fine(M)
A3: 0 | D3: 0.997 | E3: -0.04 | F3: 1
A4: 0.997 | D4: 0.999 | E4: -0.02 | F4: 0
A5: 0.999 | D5: 0.9999 | E5: 0 | F5: 0 | H5: Event Distribution Among Server types
A6: 0.9999 | D6: 1 | E6: 0.004 | F6: 0 | H6: Server Type A | I6: =B11/(B11+B12) -> 0.53094603
H7: Server Type B | I7: =B12/(B11+B12) -> 0.46905397
B10: Current | C10: Q1 | D10: Q2 | E10: Q3 | F10: Q4 | G10: Annual | H10: Delta | I10: Cost(M)
A11: Daily Events Per Server type A(old,sunfire, in M) | B11: =ServerTypeA!$B$28 -> 48.744819 | C11: =$I$6*C20/(C17*$I$6+C18*$I$7) -> 51.18206 | D11: =$I$6*D20/(D17*$I$6+D18*$I$7) -> 50.716365 | E11: =$I$6*E20/(E17*$I$6+E18*$I$7) -> 50.414619 | F11: =$I$6*F20/(F17*$I$6+F18*$I$7) -> 49.300082
A12: Daily Events Per Server type B(new,M9000, in M) | B12: =ServerTypeB!$B$28 -> 43.062665 | C12: =$I$7*C20/(C$17*$I$6+C$18*$I$7) -> 45.215798 | D12: =$I$7*D20/(D17*$I$6+D18*$I$7) -> 44.804389 | E12: =$I$7*E20/(E17*$I$6+E18*$I$7) -> 44.537817 | F12: =$I$7*F20/(F17*$I$6+F18*$I$7) -> 43.553201
A13: Peak Hour Events (19:00) Server A (m) | B13: =ServerTypeA!$B$210 -> 4.3994501 | C13: =ServerTypeA!$C$242 -> 4.6194226 | D13: =ServerTypeA!$C$274 -> 4.5773915 | E13: =ServerTypeA!$C$306 -> 4.5501574 | F13: =ServerTypeA!$C$338 -> 4.4495652
A14: Peak Hour Eevents(19:00) Server B (m) | B14: =ServerTypeB!B22 -> 4.0252025 | C14: =ServerTypeB!$C$242 -> 4.2264627 | D14: =ServerTypeB!$C$274 -> 4.188007 | E14: =ServerTypeB!$C$306 -> 4.1630896 | F14: =ServerTypeB!$C$338 -> 4.0710545
A15: Average Peak Hour CPU Server A | B15: =EXP(((B13*ServerTypeA!$C$31+ServerTypeA!$D$31)*B13+ServerTypeA!$E$31)*B13+ServerTypeA!$F$31)/100 -> 0.5720944 | C15: =EXP(((B13*ServerTypeA!$C$31+ServerTypeA!$D$31)*B13+ServerTypeA!$E$31)*B13+ServerTypeA!$F$31)/100 -> 0.5720944 | D15: =EXP(((C13*ServerTypeA!$C$31+ServerTypeA!$D$31)*C13+ServerTypeA!$E$31)*C13+ServerTypeA!$F$31)/100 -> 0.61185133 | E15: =EXP(((D13*ServerTypeA!$C$31+ServerTypeA!$D$31)*D13+ServerTypeA!$E$31)*D13+ServerTypeA!$F$31)/100 -> 0.60368942 | F15: =EXP(((E13*ServerTypeA!$C$31+ServerTypeA!$D$31)*E13+ServerTypeA!$E$31)*E13+ServerTypeA!$F$31)/100 -> 0.59855232
A16: Average Peak Hour CPU Server B | B16: =EXP(((B14*ServerTypeB!$C$31+ServerTypeB!$D$31)*B14+ServerTypeB!$E$31)*B14+ServerTypeB!$F$31)/100 -> 0.23240156 | C16: =EXP(((C14*ServerTypeB!$C$31+ServerTypeB!$D$31)*C14+ServerTypeB!$E$31)*C14+ServerTypeB!$F$31)/100 -> 0.2527423 | D16: =EXP(((D14*ServerTypeB!$C$31+ServerTypeB!$D$31)*D14+ServerTypeB!$E$31)*D14+ServerTypeB!$F$31)/100 -> 0.24848865 | E16: =EXP(((E14*ServerTypeB!$C$31+ServerTypeB!$D$31)*E14+ServerTypeB!$E$31)*E14+ServerTypeB!$F$31)/100 -> 0.24583152 | F16: =EXP(((F14*ServerTypeB!$C$31+ServerTypeB!$D$31)*F14+ServerTypeB!$E$31)*F14+ServerTypeB!$F$31)/100 -> 0.23664173
A17: Number of Servers type A(old, sunfire) | B17: 15 | C17: 15 | D17: 16 | E17: 17 | F17: 18 | H17: =F17-B17 -> 3 | I17: 0.2
A18: Number of Servers type B(new, m9000) | B18: 2 | C18: 2 | D18: 2 | E18: 2 | F18: 2 | H18: =F18-B18 -> 0 | I18: 0.1
A19: Total Servers | B19: =B17+B18 -> 17 | C19: =C17+C18 -> 17 | D19: =D17+D18 -> 18 | E19: =E17+E18 -> 19 | F19: =F17+F18 -> 20 | H19: =F19-B19 -> 3
A20: Expected Total Daily Events(M) | B20: =B11*B17+B12*B18 -> 817.29762 | C20: =C21*4/365 -> 858.1625 | D20: =D21*4/365 -> 901.07062 | E20: =E21*4/365 -> 946.12415 | F20: =F21*4/365 -> 974.50788
A21: Expected Quatarly Events(M) | B21: =365*B20/4 -> 74578.407 | C21: =B21*B22 -> 78307.328 | D21: =C21*C22 -> 82222.694 | E21: =D21*D22 -> 86333.829 | F21: =E21*E22 -> 88923.844 | G21: =SUM(C21:F21) -> 335787.69
A22: Eepected Quartely Growth in Number of Events | B22: 1.05 | C22: 1.05 | D22: 1.05 | E22: 1.03 | F22: n/a | G22: =B22*C22*D22*E22 -> 1.1923538
A23: Adjusted Quarterly Amdocs Total(M) | B23: 5 | C23: =B23*B24 -> 5.15 | D23: =C23*C24 -> 5.3045 | E23: =D23*D24 -> 5.463635 | F23: =E23*E24 -> 5.6275441
A24: Expected Quartely Growth in Amdocs Revenues | B24: 1.03 | C24: 1.03 | D24: 1.03 | E24: 1.03 | F24: n/a | G24: =PRODUCT(B24:E24) -> 1.1255088
A25: Expected Server Type A availability | B25: =ServerTypeA!$B$217 -> 0.99943213 | C25: =ServerTypeA!$B$249 -> 0.99892456 | D25: =ServerTypeA!$B$281 -> 0.99892595 | E25: =ServerTypeA!$B$313 -> 0.99905261 | F25: =ServerTypeA!$B$345 -> 0.9994241
A26: Expected Server Type B availability | B26: =ServerTypeB!$B$217 -> 1 | C26: =ServerTypeB!$B$249 -> 1 | D26: =ServerTypeB!$B$281 -> 1 | E26: =ServerTypeB!$B$313 -> 1 | F26: =ServerTypeB!$B$345 -> 1
A27: Expected Total Avialability | B27: =(B25*B11*B17+B26*B12*B18)/(B11*B17+B12*B18) -> 0.99949197 | C27: =(C25*C11*C17+C26*C12*C18)/(C11*C17+C12*C18) -> 0.99903789 | D27: =(D25*D11*D17+D26*D12*D18)/(D11*D17+D12*D18) -> 0.99903276 | E27: =(E25*E11*E17+E26*E12*E18)/(E11*E17+E12*E18) -> 0.9991418 | F27: =(F25*F11*F17+F26*F12*F18)/(F11*F17+F12*F18) -> 0.99947557
A28: Expected Amdocs Credit % | B28: =IF(B27<$D$3,$E$3,IF(B27<$D$4,$E$4,IF(B27<$D$5,$E$5,$E$6))) -> 0 | C28: =IF(C27<$D$3,$E$3,IF(C27<$D$4,$E$4,IF(C27<$D$5,$E$5,$E$6))) -> 0 | D28: =IF(D27<$D$3,$E$3,IF(D27<$D$4,$E$4,IF(D27<$D$5,$E$5,$E$6))) -> 0 | E28: =IF(E27<$D$3,$E$3,IF(E27<$D$4,$E$4,IF(E27<$D$5,$E$5,$E$6))) -> 0 | F28: =IF(F27<$D$3,$E$3,IF(F27<$D$4,$E$4,IF(F27<$D$5,$E$5,$E$6))) -> 0
A29: Expected Amdocs Fine(M) | B29: =IF(B27<$D$3,$F$3,IF(B27<$D$4,$F$4,IF(B27<$D$5,$F$5,$F$6))) -> 0 | C29: =IF(C27<$D$3,$F$3,IF(C27<$D$4,$F$4,IF(C27<$D$5,$F$5,$F$6))) -> 0 | D29: =IF(D27<$D$3,$F$3,IF(D27<$D$4,$F$4,IF(D27<$D$5,$F$5,$F$6))) -> 0 | E29: =IF(E27<$D$3,$F$3,IF(E27<$D$4,$F$4,IF(E27<$D$5,$F$5,$F$6))) -> 0 | F29: =IF(F27<$D$3,$F$3,IF(F27<$D$4,$F$4,IF(F27<$D$5,$F$5,$F$6))) -> 0 | G29: =SUM(C29:F29) -> 0
A30: Adjusted Amdocs Ratio | B30: =100%+B28 -> 1 | C30: =100%+C28 -> 1 | D30: =100%+D28 -> 1 | E30: =100%+E28 -> 1 | F30: =100%+F28 -> 1
A31: Expected Total Quaterly Amdocs Revenues(M) | B31: =B30*B23-B29 -> 5 | C31: =C30*C23-C29 -> 5.15 | D31: =D30*D23-D29 -> 5.3045 | E31: =E30*E23-E29 -> 5.463635 | F31: =F30*F23-F29 -> 5.6275441 | G31: =SUM(C31:F31) -> 21.545679 | I31: =I17*H17+I18*H18 -> 0.6

Sheet FailureForCPU
A2: Probability of failure as function of CPU utilization
A4: CPU utilization % | B4: Single Event Failure Probability | C4: Number of Failures per M events
A5: 60 | B5: 0 | C5: =1000000*B5 -> 0
A6: 90 | B6: 0.05 | C6: =1000000*B6 -> 50000
A7: 95 | B7: 0.1 | C7: =1000000*B7 -> 100000
A8: 98 | B8: 0.2 | C8: =1000000*B8 -> 200000
A9: 100 | B9: 0.5 | C9: =1000000*B9 -> 500000
A13: Every 1% step
A14: CPU | B14: Failure Probability
A15: 0 | B15: =IF(A15<$A$5,0,IF(A15<=$A$6,(A15-$A$5)*$B$6/($A$6-$A$5),IF(A15<=$A$7,$B$6+(A15-$A$6)*($B$7-$B$6)/($A$7-$A$6),IF(A15<=$A$8,$B$7+(A15-$A$7)*($B$8-$B$7)/($A$8-$A$7),$B$8+(A15-$A$8)*($B$9-$B$8)/(100-$A$8))))) -> 0
A16: 1 | B16: =IF(A16<$A$5,0,IF(A16<=$A$6,(A16-$A$5)*$B$6/($A$6-$A$5),IF(A16<=$A$7,$B$6+(A16-$A$6)*($B$7-$B$6)/($A$7-$A$6),IF(A16<=$A$8,$B$7+(A16-$A$7)*($B$8-$B$7)/($A$8-$A$7),$B$8+(A16-$A$8)*($B$9-$B$8)/(100-$A$8))))) -> 0 | D16: CPU | E16: 0 | F16: 5 | G16: 10 | H16: 15 | I16: 20 | J16: 25 | K16: 30 | L16: 35 | M16: 40 | N16: 45 | O16: 50 | P16: 55 | Q16: 60 | R16: 65 | S16: 70 | T16: 75 | U16: 80 | V16: 85 | W16: 90 | X16: 95 | Y16: 100
A17: 2 | B17: =IF(A17<$A$5,0,IF(A17<=$A$6,(A17-$A$5)*$B$6/($A$6-$A$5),IF(A17<=$A$7,$B$6+(A17-$A$6)*($B$7-$B$6)/($A$7-$A$6),IF(A17<=$A$8,$B$7+(A17-$A$7)*($B$8-$B$7)/($A$8-$A$7),$B$8+(A17-$A$8)*($B$9-$B$8)/(100-$A$8))))) -> 0 | D17: Failure Probability | E17: =IF(E16<$A$5,0,IF(E16<=$A$6,(E16-$A$5)*$B$6/($A$6-$A$5),IF(E16<=$A$7,$B$6+(E16-$A$6)*($B$7-$B$6)/($A$7-$A$6),IF(E16<=$A$8,$B$7+(E16-$A$7)*($B$8-$B$7)/($A$8-$A$7),$B$8+(E16-$A$8)*($B$9-$B$8)/(100-$A$8))))) -> 0 | F17: =IF(F16<$A$5,0,IF(F16<=$A$6,(F16-$A$5)*$B$6/($A$6-$A$5),IF(F16<=$A$7,$B$6+(F16-$A$6)*($B$7-$B$6)/($A$7-$A$6),IF(F16<=$A$8,$B$7+(F16-$A$7)*($B$8-$B$7)/($A$8-$A$7),$B$8+(F16-$A$8)*($B$9-$B$8)/(100-$A$8))))) -> 0 | G17: =IF(G16<$A$5,0,IF(G16<=$A$6,(G16-$A$5)*$B$6/($A$6-$A$5),IF(G16<=$A$7,$B$6+(G16-$A$6)*($B$7-$B$6)/($A$7-$A$6),IF(G16<=$A$8,$B$7+(G16-$A$7)*($B$8-$B$7)/($A$8-$A$7),$B$8+(G16-$A$8)*($B$9-$B$8)/(100-$A$8))))) -> 0 | H17: =IF(H16<$A$5,0,IF(H16<=$A$6,(H16-$A$5)*$B$6/($A$6-$A$5),IF(H16<=$A$7,$B$6+(H16-$A$6)*($B$7-$B$6)/($A$7-$A$6),IF(H16<=$A$8,$B$7+(H16-$A$7)*($B$8-$B$7)/($A$8-$A$7),$B$8+(H16-$A$8)*($B$9-$B$8)/(100-$A$8))))) -> 0 | I17: =IF(I16<$A$5,0,IF(I16<=$A$6,(I16-$A$5)*$B$6/($A$6-$A$5),IF(I16<=$A$7,$B$6+(I16-$A$6)*($B$7-$B$6)/($A$7-$A$6),IF(I16<=$A$8,$B$7+(I16-$A$7)*($B$8-$B$7)/($A$8-$A$7),$B$8+(I16-$A$8)*($B$9-$B$8)/(100-$A$8))))) -> 0 | J17: =IF(J16<$A$5,0,IF(J16<=$A$6,(J16-$A$5)*$B$6/($A$6-$A$5),IF(J16<=$A$7,$B$6+(J16-$A$6)*($B$7-$B$6)/($A$7-$A$6),IF(J16<=$A$8,$B$7+(J16-$A$7)*($B$8-$B$7)/($A$8-$A$7),$B$8+(J16-$A$8)*($B$9-$B$8)/(100-$A$8))))) -> 0 | K17: =IF(K16<$A$5,0,IF(K16<=$A$6,(K16-$A$5)*$B$6/($A$6-$A$5),IF(K16<=$A$7,$B$6+(K16-$A$6)*($B$7-$B$6)/($A$7-$A$6),IF(K16<=$A$8,$B$7+(K16-$A$7)*($B$8-$B$7)/($A$8-$A$7),$B$8+(K16-$A$8)*($B$9-$B$8)/(100-$A$8))))) -> 0 | L17: =IF(L16<$A$5,0,IF(L16<=$A$6,(L16-$A$5)*$B$6/($A$6-$A$5),IF(L16<=$A$7,$B$6+(L16-$A$6)*($B$7-$B$6)/($A$7-$A$6),IF(L16<=$A$8,$B$7+(L16-$A$7)*($B$8-$B$7)/($A$8-$A$7),$B$8+(L16-$A$8)*($B$9-$B$8)/(100-$A$8))))) -> 0 | ... Y17: =IF(Y16<$A$5,0,IF(Y16<=$A$6,(Y16-$A$5)*$B$6/($A$6-$A$5),IF(Y16<=$A$7,$B$6+(Y16-$A$6)*($B$7-$B$6)/($A$7-$A$6),IF(Y16<=$A$8,$B$7+(Y16-$A$7)*($B$8-$B$7)/($A$8-$A$7),$B$8+(Y16-$A$8)*($B$9-$B$8)/(100-$A$8))))) -> 0.5
A18: 3 | B18: =IF(A18<$A$5,0,IF(A18<=$A$6,(A18-$A$5)*$B$6/($A$6-$A$5),IF(A18<=$A$7,$B$6+(A18-$A$6)*($B$7-$B$6)/($A$7-$A$6),IF(A18<=$A$8,$B$7+(A18-$A$7)*($B$8-$B$7)/($A$8-$A$7),$B$8+(A18-$A$8)*($B$9-$B$8)/(100-$A$8))))) -> 0
A19: 4 | B19: =IF(A19<$A$5,0,IF(A19<=$A$6,(A19-$A$5)*$B$6/($A$6-$A$5),IF(A19<=$A$7,$B$6+(A19-$A$6)*($B$7-$B$6)/($A$7-$A$6),IF(A19<=$A$8,$B$7+(A19-$A$7)*($B$8-$B$7)/($A$8-$A$7),$B$8+(A19-$A$8)*($B$9-$B$8)/(100-$A$8))))) -> 0
A20: 5 | B20: =IF(A20<$A$5,0,IF(A20<=$A$6,(A20-$A$5)*$B$6/($A$6-$A$5),IF(A20<=$A$7,$B$6+(A20-$A$6)*($B$7-$B$6)/($A$7-$A$6),IF(A20<=$A$8,$B$7+(A20-$A$7)*($B$8-$B$7)/($A$8-$A$7),$B$8+(A20-$A$8)*($B$9-$B$8)/(100-$A$8))))) -> 0
A21: 6 | B21: =IF(A21<$A$5,0,IF(A21<=$A$6,(A21-$A$5)*$B$6/($A$6-$A$5),IF(A21<=$A$7,$B$6+(A21-$A$6)*($B$7-$B$6)/($A$7-$A$6),IF(A21<=$A$8,$B$7+(A21-$A$7)*($B$8-$B$7)/($A$8-$A$7),$B$8+(A21-$A$8)*($B$9-$B$8)/(100-$A$8))))) -> 0
A22: 7 | B22: =IF(A22<$A$5,0,IF(A22<=$A$6,(A22-$A$5)*$B$6/($A$6-$A$5),IF(A22<=$A$7,$B$6+(A22-$A$6)*($B$7-$B$6)/($A$7-$A$6),IF(A22<=$A$8,$B$7+(A22-$A$7)*($B$8-$B$7)/($A$8-$A$7),$B$8+(A22-$A$8)*($B$9-$B$8)/(100-$A$8))))) -> 0
A23: 8 | B23: =IF(A23<$A$5,0,IF(A23<=$A$6,(A23-$A$5)*$B$6/($A$6-$A$5),IF(A23<=$A$7,$B$6+(A23-$A$6)*($B$7-$B$6)/($A$7-$A$6),IF(A23<=$A$8,$B$7+(A23-$A$7)*($B$8-$B$7)/($A$8-$A$7),$B$8+(A23-$A$8)*($B$9-$B$8)/(100-$A$8))))) -> 0
A24: 9 | B24: =IF(A24<$A$5,0,IF(A24<=$A$6,(A24-$A$5)*$B$6/($A$6-$A$5),IF(A24<=$A$7,$B$6+(A24-$A$6)*($B$7-$B$6)/($A$7-$A$6),IF(A24<=$A$8,$B$7+(A24-$A$7)*($B$8-$B$7)/($A$8-$A$7),$B$8+(A24-$A$8)*($B$9-$B$8)/(100-$A$8))))) -> 0
A25: 10 | B25: =IF(A25<$A$5,0,IF(A25<=$A$6,(A25-$A$5)*$B$6/($A$6-$A$5),IF(A25<=$A$7,$B$6+(A25-$A$6)*($B$7-$B$6)/($A$7-$A$6),IF(A25<=$A$8,$B$7+(A25-$A$7)*($B$8-$B$7)/($A$8-$A$7),$B$8+(A25-$A$8)*($B$9-$B$8)/(100-$A$8))))) -> 0
A26: 11 | B26: =IF(A26<$A$5,0,IF(A26<=$A$6,(A26-$A$5)*$B$6/($A$6-$A$5),IF(A26<=$A$7,$B$6+(A26-$A$6)*($B$7-$B$6)/($A$7-$A$6),IF(A26<=$A$8,$B$7+(A26-$A$7)*($B$8-$B$7)/($A$8-$A$7),$B$8+(A26-$A$8)*($B$9-$B$8)/(100-$A$8))))) -> 0
A27: 12 | B27: =IF(A27<$A$5,0,IF(A27<=$A$6,(A27-$A$5)*$B$6/($A$6-$A$5),IF(A27<=$A$7,$B$6+(A27-$A$6)*($B$7-$B$6)/($A$7-$A$6),IF(A27<=$A$8,$B$7+(A27-$A$7)*($B$8-$B$7)/($A$8-$A$7),$B$8+(A27-$A$8)*($B$9-$B$8)/(100-$A$8))))) -> 0
A28: 13 | B28: =IF(A28<$A$5,0,IF(A28<=$A$6,(A28-$A$5)*$B$6/($A$6-$A$5),IF(A28<=$A$7,$B$6+(A28-$A$6)*($B$7-$B$6)/($A$7-$A$6),IF(A28<=$A$8,$B$7+(A28-$A$7)*($B$8-$B$7)/($A$8-$A$7),$B$8+(A28-$A$8)*($B$9-$B$8)/(100-$A$8))))) -> 0
A29: 14 | B29: =IF(A29<$A$5,0,IF(A29<=$A$6,(A29-$A$5)*$B$6/($A$6-$A$5),IF(A29<=$A$7,$B$6+(A29-$A$6)*($B$7-$B$6)/($A$7-$A$6),IF(A29<=$A$8,$B$7+(A29-$A$7)*($B$8-$B$7)/($A$8-$A$7),$B$8+(A29-$A$8)*($B$9-$B$8)/(100-$A$8))))) -> 0
... A115: 100 | B115: =IF(A115<$A$5,0,IF(A115<=$A$6,(A115-$A$5)*$B$6/($A$6-$A$5),IF(A115<=$A$7,$B$6+(A115-$A$6)*($B$7-$B$6)/($A$7-$A$6),IF(A115<=$A$8,$B$7+(A115-$A$7)*($B$8-$B$7)/($A$8-$A$7),$B$8+(A115-$A$8)*($B$9-$B$8)/(100-$A$8))))) -> 0.5

Sheet ServerTypeA
A1: Rb4-lile(average of 15 servers,old)
A2: HourOfDay | B2: Events per hr (M) | C2: Log Events Per Hour | D2: Average of log-cpu | E2: StdDev of log-cpu
A3: 0 | B3: 0.54705915 | C3: =LN(B3) -> -0.60319835 | D3: 2.7099669 | E3: 0.31307037
A4: 1 | B4: 0.30210809 | C4: =LN(B4) -> -1.1969704 | D4: 2.5235962 | E4: 0.36368963
A5: 2 | B5: 0.19123857 | C5: =LN(B5) -> -1.6542336 | D5: 2.4103539 | E5: 0.39784695
A6: 3 | B6: 0.17781026 | C6: =LN(B6) -> -1.7270383 | D6: 2.3554325 | E6: 0.40235057
A7: 4 | B7: 0.35924234 | C7: =LN(B7) -> -1.0237581 | D7: 2.5455343 | E7: 0.36443338
A8: 5 | B8: 0.95434751 | C8: =LN(B8) -> -0.046727409 | D8: 2.9667048 | E8: 0.27281514
A9: 6 | B9: 1.3952391 | C9: =LN(B9) -> 0.3330658 | D9: 3.2003399 | E9: 0.21703426
A10: 7 | B10: 1.6468302 | C10: =LN(B10) -> 0.49885237 | D10: 3.3054725 | E10: 0.2163628
A11: 8 | B11: 1.8977111 | C11: =LN(B11) -> 0.6406485 | D11: 3.410284 | E11: 0.21035771
A12: 9 | B12: 2.1127481 | C12: =LN(B12) -> 0.74798949 | D12: 3.4873616 | E12: 0.19342712
A13: 10 | B13: 2.2471278 | C13: =LN(B13) -> 0.80965286 | D13: 3.5408984 | E13: 0.18034252
A14: 11 | B14: 2.3458745 | C14: =LN(B14) -> 0.85265824 | D14: 3.5532207 | E14: 0.17363274
... A26: 23 | B26: 1.0004341 | C26: =LN(B26) -> 0.00043397915 | D26: 3.0199697 | E26: 0.28172777
A28: Total | B28: =SUM(B3:B26) -> 48.744819
B29: Regression from number of events to log-CPU
C30: x^3 | D30: x^2 | E30: x | F30: c
B31: Coeff | C31: {=LINEST(D3:D26,B3:B26^{1,2,3})} -> 0.022406006 | D31: -0.22547508 | E31: 0.97180655 | F31: 2.2274934
B34: Regression from log of number of events to std of log CPU
C35: ln(EPH) | D35: C
B36: Coeff | C36: {=LINEST(E3:E26,C3:C26)} -> -0.092492832 | D36: 0.25603831
A39: Prediction | K39: Commulative Distribution (Probability CPU is less)
A41: EPH(in M) | B41: Log-EPH | C41: Log-CPU | D41: CPU | E41: STD of LOG-CPU | F41: 0.0 | G41: 2.5 | H41: 7.5 | I41: 12.5 | J41: 17.5 | K41: 21.5 | L41: 26.5 | M41: 31.5 | N41: 36.5 | O41: 41.5 | P41: 46.5 | Q41: 51.5 | R41: 56.5 | S41: 61.5 | T41: 66.5 | U41: 71.5 | V41: 76.5 | W41: 81.5 | X41: 86.5 | Y41: 91.5 | Z41: 96.5 | AA41: 101.5
A42: 0.1 | B42: =LN(A42) -> -2.3025851 | C42: =((A42*$C$31+$D$31)*A42+$E$31)*A42+$F$31 -> 2.3224417 | D42: =EXP(C42) -> 10.20055 | E42: =$C$36*B42+$D$36 -> 0.46901092 | F42: 0 | G42: =NORMDIST(LN(G$41),$C42,$E42,TRUE) -> 0.0013582543 | H42: =NORMDIST(LN(H$41),$C42,$E42,TRUE) -> 0.25600297 | I42: =NORMDIST(LN(I$41),$C42,$E42,TRUE) -> 0.66765156 | J42: =NORMDIST(LN(J$41),$C42,$E42,TRUE) -> 0.87510214 | K42: =NORMDIST(LN(K$41),$C42,$E42,TRUE) -> 0.94405469 | L42: =NORMDIST(LN(L$41),$C42,$E42,TRUE) -> 0.97910306 | M42: =NORMDIST(LN(M$41),$C42,$E42,TRUE) -> 0.99189368 | N42: =NORMDIST(LN(N$41),$C42,$E42,TRUE) -> 0.9967182 | ... Z42: =NORMDIST(LN(Z$41),$C42,$E42,TRUE) -> 0.99999917 | AA42: 1
A43: 0.2 | B43: =LN(A43) -> -1.6094379 | C43: =((A43*$C$31+$D$31)*A43+$E$31)*A43+$F$31 -> 2.4130149 | D43: =EXP(C43) -> 11.16758 | E43: =$C$36*B43+$D$36 -> 0.40489978 | F43: 0 | G43: =NORMDIST(LN(G$41),$C43,$E43,TRUE) -> 0.00010928321 | H43: =NORMDIST(LN(H$41),$C43,$E43,TRUE) -> 0.16274574 | I43: =NORMDIST(LN(I$41),$C43,$E43,TRUE) -> 0.60963752 | J43: =NORMDIST(LN(J$41),$C43,$E43,TRUE) -> 0.86636593 | K43: =NORMDIST(LN(K$41),$C43,$E43,TRUE) -> 0.94714479 | L43: =NORMDIST(LN(L$41),$C43,$E43,TRUE) -> 0.98358606 | M43: =NORMDIST(LN(M$41),$C43,$E43,TRUE) -> 0.99478233 | N43: =NORMDIST(LN(N$41),$C43,$E43,TRUE) -> 0.99827725 | ... Z43: =NORMDIST(LN(Z$41),$C43,$E43,TRUE) -> 0.99999995 | AA43: 1
A44: 0.3 | B44: =LN(A44) -> -1.2039728 | C44: =((A44*$C$31+$D$31)*A44+$E$31)*A44+$F$31 -> 2.4993475 | D44: =EXP(C44) -> 12.174548 | E44: =$C$36*B44+$D$36 -> 0.36739716 | F44: 0 | G44: =NORMDIST(LN(G$41),$C44,$E44,TRUE) -> 8.2055294e-06 | H44: =NORMDIST(LN(H$41),$C44,$E44,TRUE) -> 0.093653891 | I44: =NORMDIST(LN(I$41),$C44,$E44,TRUE) -> 0.52862163 | J44: =NORMDIST(LN(J$41),$C44,$E44,TRUE) -> 0.83833365 | K44: =NORMDIST(LN(K$41),$C44,$E44,TRUE) -> 0.93918053 | L44: =NORMDIST(LN(L$41),$C44,$E44,TRUE) -> 0.98287209 | M44: =NORMDIST(LN(M$41),$C44,$E44,TRUE) -> 0.99516624 | N44: =NORMDIST(LN(N$41),$C44,$E44,TRUE) -> 0.99859823 | ... Z44: =NORMDIST(LN(Z$41),$C44,$E44,TRUE) -> 0.99999999 | AA44: 1
A45: 0.4 | B45: =LN(A45) -> -0.91629073 | C45: =((A45*$C$31+$D$31)*A45+$E$31)*A45+$F$31 -> 2.5815739 | D45: =EXP(C45) -> 13.217926 | E45: =$C$36*B45+$D$36 -> 0.34078863 | F45: 0 | G45: =NORMDIST(LN(G$41),$C45,$E45,TRUE) -> 5.130721e-07 | H45: =NORMDIST(LN(H$41),$C45,$E45,TRUE) -> 0.048174008 | I45: =NORMDIST(LN(I$41),$C45,$E45,TRUE) -> 0.43491643 | J45: =NORMDIST(LN(J$41),$C45,$E45,TRUE) -> 0.79487771 | K45: =NORMDIST(LN(K$41),$C45,$E45,TRUE) -> 0.92328345 | L45: =NORMDIST(LN(L$41),$C45,$E45,TRUE) -> 0.97937768 | M45: =NORMDIST(LN(M$41),$C45,$E45,TRUE) -> 0.99458671 | N45: =NORMDIST(LN(N$41),$C45,$E45,TRUE) -> 0.99856135 | ... Z45: =NORMDIST(LN(Z$41),$C45,$E45,TRUE) -> 1 | AA45: 1
A46: 0.5 | B46: =LN(A46) -> -0.69314718 | C46: =((A46*$C$31+$D$31)*A46+$E$31)*A46+$F$31 -> 2.6598286 | D46: =EXP(C46) -> 14.293839 | E46: =$C$36*B46+$D$36 -> 0.32014945 | F46: 0 | G46: =NORMDIST(LN(G$41),$C46,$E46,TRUE) -> 2.5755776e-08 | H46: =NORMDIST(LN(H$41),$C46,$E46,TRUE) -> 0.021981068 | I46: =NORMDIST(LN(I$41),$C46,$E46,TRUE) -> 0.33765675 | J46: =NORMDIST(LN(J$41),$C46,$E46,TRUE) -> 0.73634515 | K46: =NORMDIST(LN(K$41),$C46,$E46,TRUE) -> 0.89886405 | L46: =NORMDIST(LN(L$41),$C46,$E46,TRUE) -> 0.97308564 | M46: =NORMDIST(LN(M$41),$C46,$E46,TRUE) -> 0.99320827 | N46: =NORMDIST(LN(N$41),$C46,$E46,TRUE) -> 0.99829572 | ... Z46: =NORMDIST(LN(Z$41),$C46,$E46,TRUE) -> 1 | AA46: 1
A47: 0.6 | B47: =LN(A47) -> -0.51082562 | C47: =((A47*$C$31+$D$31)*A47+$E$31)*A47+$F$31 -> 2.734246 | D47: =EXP(C47) -> 15.398128 | E47: =$C$36*B47+$D$36 -> 0.30328602 | F47: 0 | G47: =NORMDIST(LN(G$41),$C47,$E47,TRUE) -> 1.0224854e-09 | H47: =NORMDIST(LN(H$41),$C47,$E47,TRUE) -> 0.0088501112 | I47: =NORMDIST(LN(I$41),$C47,$E47,TRUE) -> 0.24587536 | J47: =NORMDIST(LN(J$41),$C47,$E47,TRUE) -> 0.66344926 | K47: =NORMDIST(LN(K$41),$C47,$E47,TRUE) -> 0.86447207 | L47: =NORMDIST(LN(L$41),$C47,$E47,TRUE) -> 0.9632775 | M47: =NORMDIST(LN(M$41),$C47,$E47,TRUE) -> 0.99086144 | N47: =NORMDIST(LN(N$41),$C47,$E47,TRUE) -> 0.99778443 | ... Z47: =NORMDIST(LN(Z$41),$C47,$E47,TRUE) -> 1 | AA47: 1
A48: 0.7 | B48: =LN(A48) -> -0.35667494 | C48: =((A48*$C$31+$D$31)*A48+$E$31)*A48+$F$31 -> 2.8049604 | D48: =EXP(C48) -> 16.526422 | E48: =$C$36*B48+$D$36 -> 0.28902818 | F48: 0 | G48: =NORMDIST(LN(G$41),$C48,$E48,TRUE) -> 3.1900117e-11 | H48: =NORMDIST(LN(H$41),$C48,$E48,TRUE) -> 0.0031332939 | I48: =NORMDIST(LN(I$41),$C48,$E48,TRUE) -> 0.16699565 | J48: =NORMDIST(LN(J$41),$C48,$E48,TRUE) -> 0.57849491 | K48: =NORMDIST(LN(K$41),$C48,$E48,TRUE) -> 0.81865887 | L48: =NORMDIST(LN(L$41),$C48,$E48,TRUE) -> 0.9488387 | M48: =NORMDIST(LN(M$41),$C48,$E48,TRUE) -> 0.98718294 | N48: =NORMDIST(LN(N$41),$C48,$E48,TRUE) -> 0.99694142 | ... Z48: =NORMDIST(LN(Z$41),$C48,$E48,TRUE) -> 1 | AA48: 1
A49: 0.8 | B49: =LN(A49) -> -0.22314355 | C49: =((A49*$C$31+$D$31)*A49+$E$31)*A49+$F$31 -> 2.8721064 | D49: =EXP(C49) -> 17.674208 | E49: =$C$36*B49+$D$36 -> 0.27667749 | F49: 0 | G49: =NORMDIST(LN(G$41),$C49,$E49,TRUE) -> 7.8062556e-13 | H49: =NORMDIST(LN(H$41),$C49,$E49,TRUE) -> 0.00097348551 | I49: =NORMDIST(LN(I$41),$C49,$E49,TRUE) -> 0.10529971 | J49: =NORMDIST(LN(J$41),$C49,$E49,TRUE) -> 0.48572022 | K49: =NORMDIST(LN(K$41),$C49,$E49,TRUE) -> 0.76059342 | L49: =NORMDIST(LN(L$41),$C49,$E49,TRUE) -> 0.92839437 | M49: =NORMDIST(LN(M$41),$C49,$E49,TRUE) -> 0.98163017 | N49: =NORMDIST(LN(N$41),$C49,$E49,TRUE) -> 0.99561797 | ... Z49: =NORMDIST(LN(Z$41),$C49,$E49,TRUE) -> 1 | AA49: 1
A50: 0.9 | B50: =LN(A50) -> -0.10536052 | C50: =((A50*$C$31+$D$31)*A50+$E$31)*A50+$F$31 -> 2.9358184 | D50: =EXP(C50) -> 18.836913 | E50: =$C$36*B50+$D$36 -> 0.2657834 | F50: 0 | G50: =NORMDIST(LN(G$41),$C50,$E50,TRUE) -> 1.4991111e-14 | H50: =NORMDIST(LN(H$41),$C50,$E50,TRUE) -> 0.00026520508 | I50: =NORMDIST(LN(I$41),$C50,$E50,TRUE) -> 0.061421785 | J50: =NORMDIST(LN(J$41),$C50,$E50,TRUE) -> 0.39089651 | K50: =NORMDIST(LN(K$41),$C50,$E50,TRUE) -> 0.6905914 | L50: =NORMDIST(LN(L$41),$C50,$E50,TRUE) -> 0.9004688 | M50: =NORMDIST(LN(M$41),$C50,$E50,TRUE) -> 0.97347673 | N50: =NORMDIST(LN(N$41),$C50,$E50,TRUE) -> 0.99359207 | ... Z50: =NORMDIST(LN(Z$41),$C50,$E50,TRUE) -> 1 | AA50: 1
A51: 1 | B51: =LN(A51) -> 0 | C51: =((A51*$C$31+$D$31)*A51+$E$31)*A51+$F$31 -> 2.9962308 | D51: =EXP(C51) -> 20.009974 | E51: =$C$36*B51+$D$36 -> 0.25603831 | F51: 0 | G51: =NORMDIST(LN(G$41),$C51,$E51,TRUE) -> 2.2637022e-16 | H51: =NORMDIST(LN(H$41),$C51,$E51,TRUE) -> 6.3362385e-05 | I51: =NORMDIST(LN(I$41),$C51,$E51,TRUE) -> 0.033058901 | J51: =NORMDIST(LN(J$41),$C51,$E51,TRUE) -> 0.30032147 | K51: =NORMDIST(LN(K$41),$C51,$E51,TRUE) -> 0.61045807 | L51: =NORMDIST(LN(L$41),$C51,$E51,TRUE) -> 0.86371334 | M51: =NORMDIST(LN(M$41),$C51,$E51,TRUE) -> 0.96182114 | N51: =NORMDIST(LN(N$41),$C51,$E51,TRUE) -> 0.99055318 | ... Z51: =NORMDIST(LN(Z$41),$C51,$E51,TRUE) -> 1 | AA51: 1
A52: 1.1 | B52: =LN(A52) -> 0.09531018 | C52: =((A52*$C$31+$D$31)*A52+$E$31)*A52+$F$31 -> 3.0534781 | D52: =EXP(C52) -> 21.188914 | E52: =$C$36*B52+$D$36 -> 0.2472228 | F52: 0 | G52: =NORMDIST(LN(G$41),$C52,$E52,TRUE) -> 2.6953888e-18 | H52: =NORMDIST(LN(H$41),$C52,$E52,TRUE) -> 1.3288803e-05 | I52: =NORMDIST(LN(I$41),$C52,$E52,TRUE) -> 0.016392273 | J52: =NORMDIST(LN(J$41),$C52,$E52,TRUE) -> 0.21955298 | K52: =NORMDIST(LN(K$41),$C52,$E52,TRUE) -> 0.52350572 | L52: =NORMDIST(LN(L$41),$C52,$E52,TRUE) -> 0.81719229 | M52: =NORMDIST(LN(M$41),$C52,$E52,TRUE) -> 0.94562695 | N52: =NORMDIST(LN(N$41),$C52,$E52,TRUE) -> 0.98608851 | ... Z52: =NORMDIST(LN(Z$41),$C52,$E52,TRUE) -> 1 | AA52: 1
A53: 1.2 | B53: =LN(A53) -> 0.18232156 | C53: =((A53*$C$31+$D$31)*A53+$E$31)*A53+$F$31 -> 3.1076947 | D53: =EXP(C53) -> 22.369416 | E53: =$C$36*B53+$D$36 -> 0.23917487 | F53: 0 | G53: =NORMDIST(LN(G$41),$C53,$E53,TRUE) -> 2.5389541e-20 | H53: =NORMDIST(LN(H$41),$C53,$E53,TRUE) -> 2.4502018e-06 | I53: =NORMDIST(LN(I$41),$C53,$E53,TRUE) -> 0.0074825198 | J53: =NORMDIST(LN(J$41),$C53,$E53,TRUE) -> 0.1523469 | K53: =NORMDIST(LN(K$41),$C53,$E53,TRUE) -> 0.4341793 | L53: =NORMDIST(LN(L$41),$C53,$E53,TRUE) -> 0.76067566 | M53: =NORMDIST(LN(M$41),$C53,$E53,TRUE) -> 0.92380504 | N53: =NORMDIST(LN(N$41),$C53,$E53,TRUE) -> 0.97967642 | ... Z53: =NORMDIST(LN(Z$41),$C53,$E53,TRUE) -> 1 | AA53: 1
... A101: 6 | B101: =LN(A101) -> 1.7917595 | C101: =((A101*$C$31+$D$31)*A101+$E$31)*A101+$F$31 -> 4.780927 | D101: =EXP(C101) -> 119.21481 | E101: =$C$36*B101+$D$36 -> 0.090313399 | F101: 0 | G101: =NORMDIST(LN(G$41),$C101,$E101,TRUE) -> 0 | H101: =NORMDIST(LN(H$41),$C101,$E101,TRUE) -> 2.6794671e-206 | I101: =NORMDIST(LN(I$41),$C101,$E101,TRUE) -> 6.3467039e-138 | J101: =NORMDIST(LN(J$41),$C101,$E101,TRUE) -> 1.8257803e-100 | K101: =NORMDIST(LN(K$41),$C101,$E101,TRUE) -> 1.6322596e-80 | L101: =NORMDIST(LN(L$41),$C101,$E101,TRUE) -> 1.4951612e-62 | M101: =NORMDIST(LN(M$41),$C101,$E101,TRUE) -> 1.8677424e-49 | N101: =NORMDIST(LN(N$41),$C101,$E101,TRUE) -> 1.5284052e-39 | ... Z101: =NORMDIST(LN(Z$41),$C101,$E101,TRUE) -> 0.009627412 | AA101: 1
A104: Probability Distribution for CPU to fall into bin ventered at each 5% step
A105: EPH(in M) | B105: 0 | C105: 5 | D105: 10 | E105: 15 | F105: 20 | G105: 25 | H105: 30 | I105: 35 | J105: 40 | K105: 45 | L105: 50 | M105: 55 | N105: 60 | O105: 65 | P105: 70 | Q105: 75 | R105: 80 | S105: 85 | T105: 90 | U105: 95 | V105: 100
A106: 0.1 | B106: 0 | C106: =H42-G42 -> 0.25464472 | D106: =I42-H42 -> 0.41164859 | E106: =J42-I42 -> 0.20745058 | F106: =K42-J42 -> 0.068952549 | G106: =L42-K42 -> 0.03504837 | H106: =M42-L42 -> 0.012790613 | I106: =N42-M42 -> 0.0048245244 | J106: =O42-N42 -> 0.0018957382 | ... V106: =AA42-Z42 -> 8.2914343e-07
...

Sheet ServerTypeB
A1: rb31,32(new, average of 2 servers)
A2: HourOfDay | B2: Events per hr (M) | C2: Log Events Per Hour | D2: Average of log-cpu | E2: StdDev of log-cpu
A3: 0 | B3: 0.43929673 | C3: =LN(B3) -> -0.82258016 | D3: 1.4578535 | E3: 0.38068831
A4: 1 | B4: 0.24725845 | C4: =LN(B4) -> -1.3973211 | D4: 1.2009059 | E4: 0.44643345
A5: 2 | B5: 0.15990047 | C5: =LN(B5) -> -1.8332037 | D5: 1.1239122 | E5: 0.47421592
A6: 3 | B6: 0.156343 | C6: =LN(B6) -> -1.855703 | D6: 1.0781775 | E6: 0.47328223
A7: 4 | B7: 0.33371847 | C7: =LN(B7) -> -1.0974576 | D7: 1.358616 | E7: 0.42022277
A8: 5 | B8: 0.89391525 | C8: =LN(B8) -> -0.11214431 | D8: 1.8935671 | E8: 0.29032631
A9: 6 | B9: 1.2472559 | C9: =LN(B9) -> 0.22094583 | D9: 2.1777567 | E9: 0.26108808
A10: 7 | B10: 1.4274515 | C10: =LN(B10) -> 0.35589066 | D10: 2.2830567 | E10: 0.27475598
A11: 8 | B11: 1.6331403 | C11: =LN(B11) -> 0.4905047 | D11: 2.4016786 | E11: 0.26257045
A12: 9 | B12: 1.807974 | C12: =LN(B12) -> 0.59220686 | D12: 2.4780892 | E12: 0.24747045
A13: 10 | B13: 1.9315643 | C13: =LN(B13) -> 0.6583302 | D13: 2.5417076 | E13: 0.23582719
A14: 11 | B14: 2.0302242 | C14: =LN(B14) -> 0.70814621 | D14: 2.5496839 | E14: 0.21494478
... A26: 23 | B26: 0.81373062 | C26: =LN(B26) -> -0.2061259 | D26: 1.8025718 | E26: 0.37336173
A28: Total | B28: =SUM(B3:B26) -> 43.062665
B29: Regression from number of events to log-CPU
C30: x^3 | D30: x^2 | E30: x | F30: c
B31: Coeff | C31: {=LINEST(D3:D26,B3:B26^{1,2,3})} -> 0.044060711 | D31: -0.39773935 | E31: 1.4483879 | F31: 0.88657835
B34: Regression from log of number of events to std of log CPU
C35: ln(EPH) | D35: C
B36: Coeff | C36: {=LINEST(E3:E26,C3:C26)} -> -0.11017706 | D36: 0.28969066
A39: Prediction | K39: Commulative Distribution (Probability CPU is less)
A41: EPH(in M) | B41: Log-EPH | C41: Log-CPU | D41: CPU | E41: STD of LOG-CPU | F41: 0.0 | G41: 2.5 | H41: 7.5 | I41: 12.5 | J41: 17.5 | K41: 21.5 | L41: 26.5 | M41: 31.5 | N41: 36.5 | O41: 41.5 | P41: 46.5 | Q41: 51.5 | R41: 56.5 | S41: 61.5 | T41: 66.5 | U41: 71.5 | V41: 76.5 | W41: 81.5 | X41: 86.5 | Y41: 91.5 | Z41: 96.5 | AA41: 101.5
A42: 0.1 | B42: =LN(A42) -> -2.3025851 | C42: =((A42*$C$31+$D$31)*A42+$E$31)*A42+$F$31 -> 1.0274838 | D42: =EXP(C42) -> 2.7940267 | E42: =$C$36*B42+$D$36 -> 0.54338272 | F42: 0 | G42: =NORMDIST(LN(G$41),$C42,$E42,TRUE) -> 0.41893013 | H42: =NORMDIST(LN(H$41),$C42,$E42,TRUE) -> 0.96540452 | I42: =NORMDIST(LN(I$41),$C42,$E42,TRUE) -> 0.99708556 | J42: =NORMDIST(LN(J$41),$C42,$E42,TRUE) -> 0.99963289 | K42: =NORMDIST(LN(K$41),$C42,$E42,TRUE) -> 0.99991344 | L42: =NORMDIST(LN(L$41),$C42,$E42,TRUE) -> 0.99998264 | M42: =NORMDIST(LN(M$41),$C42,$E42,TRUE) -> 0.99999587 | N42: =NORMDIST(LN(N$41),$C42,$E42,TRUE) -> 0.99999887 | ... Z42: =NORMDIST(LN(Z$41),$C42,$E42,TRUE) -> 1 | AA42: 1
A43: 0.2 | B43: =LN(A43) -> -1.6094379 | C43: =((A43*$C$31+$D$31)*A43+$E$31)*A43+$F$31 -> 1.1606988 | D43: =EXP(C43) -> 3.1921633 | E43: =$C$36*B43+$D$36 -> 0.4670138 | F43: 0 | G43: =NORMDIST(LN(G$41),$C43,$E43,TRUE) -> 0.30036802 | H43: =NORMDIST(LN(H$41),$C43,$E43,TRUE) -> 0.96630596 | I43: =NORMDIST(LN(I$41),$C43,$E43,TRUE) -> 0.998266 | J43: =NORMDIST(LN(J$41),$C43,$E43,TRUE) -> 0.99986545 | K43: =NORMDIST(LN(K$41),$C43,$E43,TRUE) -> 0.99997788 | L43: =NORMDIST(LN(L$41),$C43,$E43,TRUE) -> 0.99999708 | M43: =NORMDIST(LN(M$41),$C43,$E43,TRUE) -> 0.99999953 | N43: =NORMDIST(LN(N$41),$C43,$E43,TRUE) -> 0.99999991 | ... Z43: =NORMDIST(LN(Z$41),$C43,$E43,TRUE) -> 1 | AA43: 1
A44: 0.3 | B44: =LN(A44) -> -1.2039728 | C44: =((A44*$C$31+$D$31)*A44+$E$31)*A44+$F$31 -> 1.2864878 | D44: =EXP(C44) -> 3.6200499 | E44: =$C$36*B44+$D$36 -> 0.42234085 | F44: 0 | G44: =NORMDIST(LN(G$41),$C44,$E44,TRUE) -> 0.19036928 | H44: =NORMDIST(LN(H$41),$C44,$E44,TRUE) -> 0.95771007 | I44: =NORMDIST(LN(I$41),$C44,$E44,TRUE) -> 0.99832806 | J44: =NORMDIST(LN(J$41),$C44,$E44,TRUE) -> 0.9999046 | K44: =NORMDIST(LN(K$41),$C44,$E44,TRUE) -> 0.99998769 | L44: =NORMDIST(LN(L$41),$C44,$E44,TRUE) -> 0.99999878 | M44: =NORMDIST(LN(M$41),$C44,$E44,TRUE) -> 0.99999985 | N44: =NORMDIST(LN(N$41),$C44,$E44,TRUE) -> 0.99999998 | ... Z44: =NORMDIST(LN(Z$41),$C44,$E44,TRUE) -> 1 | AA44: 1
A45: 0.4 | B45: =LN(A45) -> -0.91629073 | C45: =((A45*$C$31+$D$31)*A45+$E$31)*A45+$F$31 -> 1.4051151 | D45: =EXP(C45) -> 4.0759958 | E45: =$C$36*B45+$D$36 -> 0.39064488 | F45: 0 | G45: =NORMDIST(LN(G$41),$C45,$E45,TRUE) -> 0.10540766 | H45: =NORMDIST(LN(H$41),$C45,$E45,TRUE) -> 0.94073549 | I45: =NORMDIST(LN(I$41),$C45,$E45,TRUE) -> 0.9979387 | J45: =NORMDIST(LN(J$41),$C45,$E45,TRUE) -> 0.99990424 | K45: =NORMDIST(LN(K$41),$C45,$E45,TRUE) -> 0.99998964 | L45: =NORMDIST(LN(L$41),$C45,$E45,TRUE) -> 0.99999917 | M45: =NORMDIST(LN(M$41),$C45,$E45,TRUE) -> 0.99999992 | N45: =NORMDIST(LN(N$41),$C45,$E45,TRUE) -> 0.99999999 | ... Z45: =NORMDIST(LN(Z$41),$C45,$E45,TRUE) -> 1 | AA45: 1
A46: 0.5 | B46: =LN(A46) -> -0.69314718 | C46: =((A46*$C$31+$D$31)*A46+$E$31)*A46+$F$31 -> 1.516845 | D46: =EXP(C46) -> 4.5578227 | E46: =$C$36*B46+$D$36 -> 0.36605958 | F46: 0 | G46: =NORMDIST(LN(G$41),$C46,$E46,TRUE) -> 0.050441102 | H46: =NORMDIST(LN(H$41),$C46,$E46,TRUE) -> 0.91317878 | I46: =NORMDIST(LN(I$41),$C46,$E46,TRUE) -> 0.99707492 | J46: =NORMDIST(LN(J$41),$C46,$E46,TRUE) -> 0.99988119 | K46: =NORMDIST(LN(K$41),$C46,$E46,TRUE) -> 0.9999887 | L46: =NORMDIST(LN(L$41),$C46,$E46,TRUE) -> 0.99999924 | M46: =NORMDIST(LN(M$41),$C46,$E46,TRUE) -> 0.99999994 | N46: =NORMDIST(LN(N$41),$C46,$E46,TRUE) -> 0.99999999 | ... Z46: =NORMDIST(LN(Z$41),$C46,$E46,TRUE) -> 1 | AA46: 1
A47: 0.6 | B47: =LN(A47) -> -0.51082562 | C47: =((A47*$C$31+$D$31)*A47+$E$31)*A47+$F$31 -> 1.621942 | D47: =EXP(C47) -> 5.062913 | E47: =$C$36*B47+$D$36 -> 0.34597193 | F47: 0 | G47: =NORMDIST(LN(G$41),$C47,$E47,TRUE) -> 0.020694091 | H47: =NORMDIST(LN(H$41),$C47,$E47,TRUE) -> 0.87198354 | I47: =NORMDIST(LN(I$41),$C47,$E47,TRUE) -> 0.99550339 | J47: =NORMDIST(LN(J$41),$C47,$E47,TRUE) -> 0.99983137 | K47: =NORMDIST(LN(K$41),$C47,$E47,TRUE) -> 0.99998541 | L47: =NORMDIST(LN(L$41),$C47,$E47,TRUE) -> 0.99999914 | M47: =NORMDIST(LN(M$41),$C47,$E47,TRUE) -> 0.99999994 | N47: =NORMDIST(LN(N$41),$C47,$E47,TRUE) -> 0.99999999 | ... Z47: =NORMDIST(LN(Z$41),$C47,$E47,TRUE) -> 1 | AA47: 1
A48: 0.7 | B48: =LN(A48) -> -0.35667494 | C48: =((A48*$C$31+$D$31)*A48+$E$31)*A48+$F$31 -> 1.7206704 | D48: =EXP(C48) -> 5.5882736 | E48: =$C$36*B48+$D$36 -> 0.32898806 | F48: 0 | G48: =NORMDIST(LN(G$41),$C48,$E48,TRUE) -> 0.0072423713 | H48: =NORMDIST(LN(H$41),$C48,$E48,TRUE) -> 0.81443442 | I48: =NORMDIST(LN(I$41),$C48,$E48,TRUE) -> 0.99279894 | J48: =NORMDIST(LN(J$41),$C48,$E48,TRUE) -> 0.9997396 | K48: =NORMDIST(LN(K$41),$C48,$E48,TRUE) -> 0.99997894 | L48: =NORMDIST(LN(L$41),$C48,$E48,TRUE) -> 0.99999888 | M48: =NORMDIST(LN(M$41),$C48,$E48,TRUE) -> 0.99999993 | N48: =NORMDIST(LN(N$41),$C48,$E48,TRUE) -> 0.99999999 | ... Z48: =NORMDIST(LN(Z$41),$C48,$E48,TRUE) -> 1 | AA48: 1
A49: 0.8 | B49: =LN(A49) -> -0.22314355 | C49: =((A49*$C$31+$D$31)*A49+$E$31)*A49+$F$31 -> 1.8132945 | D49: =EXP(C49) -> 6.1306118 | E49: =$C$36*B49+$D$36 -> 0.31427596 | F49: 0 | G49: =NORMDIST(LN(G$41),$C49,$E49,TRUE) -> 0.002157325 | H49: =NORMDIST(LN(H$41),$C49,$E49,TRUE) -> 0.73940152 | I49: =NORMDIST(LN(I$41),$C49,$E49,TRUE) -> 0.98830202 | J49: =NORMDIST(LN(J$41),$C49,$E49,TRUE) -> 0.99957737 | K49: =NORMDIST(LN(K$41),$C49,$E49,TRUE) -> 0.99996731 | L49: =NORMDIST(LN(L$41),$C49,$E49,TRUE) -> 0.9999984 | M49: =NORMDIST(LN(M$41),$C49,$E49,TRUE) -> 0.9999999 | N49: =NORMDIST(LN(N$41),$C49,$E49,TRUE) -> 0.99999999 | ... Z49: =NORMDIST(LN(Z$41),$C49,$E49,TRUE) -> 1 | AA49: 1
A50: 0.9 | B50: =LN(A50) -> -0.10536052 | C50: =((A50*$C$31+$D$31)*A50+$E$31)*A50+$F$31 -> 1.9000788 | D50: =EXP(C50) -> 6.6864214 | E50: =$C$36*B50+$D$36 -> 0.30129897 | F50: 0 | G50: =NORMDIST(LN(G$41),$C50,$E50,TRUE) -> 0.00054701946 | H50: =NORMDIST(LN(H$41),$C50,$E50,TRUE) -> 0.64843445 | I50: =NORMDIST(LN(I$41),$C50,$E50,TRUE) -> 0.98107652 | J50: =NORMDIST(LN(J$41),$C50,$E50,TRUE) -> 0.99929659 | K50: =NORMDIST(LN(K$41),$C50,$E50,TRUE) -> 0.99994701 | L50: =NORMDIST(LN(L$41),$C50,$E50,TRUE) -> 0.99999757 | M50: =NORMDIST(LN(M$41),$C50,$E50,TRUE) -> 0.99999987 | N50: =NORMDIST(LN(N$41),$C50,$E50,TRUE) -> 0.99999999 | ... Z50: =NORMDIST(LN(Z$41),$C50,$E50,TRUE) -> 1 | AA50: 1
A51: 1 | B51: =LN(A51) -> 0 | C51: =((A51*$C$31+$D$31)*A51+$E$31)*A51+$F$31 -> 1.9812876 | D51: =EXP(C51) -> 7.2520746 | E51: =$C$36*B51+$D$36 -> 0.28969066 | F51: 0 | G51: =NORMDIST(LN(G$41),$C51,$E51,TRUE) -> 0.0001183093 | H51: =NORMDIST(LN(H$41),$C51,$E51,TRUE) -> 0.54618922 | I51: =NORMDIST(LN(I$41),$C51,$E51,TRUE) -> 0.96990421 | J51: =NORMDIST(LN(J$41),$C51,$E51,TRUE) -> 0.99882054 | K51: =NORMDIST(LN(K$41),$C51,$E51,TRUE) -> 0.9999121 | L51: =NORMDIST(LN(L$41),$C51,$E51,TRUE) -> 0.99999615 | M51: =NORMDIST(LN(M$41),$C51,$E51,TRUE) -> 0.9999998 | N51: =NORMDIST(LN(N$41),$C51,$E51,TRUE) -> 0.99999999 | ... Z51: =NORMDIST(LN(Z$41),$C51,$E51,TRUE) -> 1 | AA51: 1
A52: 1.1 | B52: =LN(A52) -> 0.09531018 | C52: =((A52*$C$31+$D$31)*A52+$E$31)*A52+$F$31 -> 2.0571852 | D52: =EXP(C52) -> 7.823916 | E52: =$C$36*B52+$D$36 -> 0.27918967 | F52: 0 | G52: =NORMDIST(LN(G$41),$C52,$E52,TRUE) -> 2.190124e-05 | H52: =NORMDIST(LN(H$41),$C52,$E52,TRUE) -> 0.43981192 | I52: =NORMDIST(LN(I$41),$C52,$E52,TRUE) -> 0.95334854 | J52: =NORMDIST(LN(J$41),$C52,$E52,TRUE) -> 0.99803297 | K52: =NORMDIST(LN(K$41),$C52,$E52,TRUE) -> 0.99985311 | L52: =NORMDIST(LN(L$41),$C52,$E52,TRUE) -> 0.99999378 | M52: =NORMDIST(LN(M$41),$C52,$E52,TRUE) -> 0.9999997 | N52: =NORMDIST(LN(N$41),$C52,$E52,TRUE) -> 0.99999998 | ... Z52: =NORMDIST(LN(Z$41),$C52,$E52,TRUE) -> 1 | AA52: 1
A53: 1.2 | B53: =LN(A53) -> 0.18232156 | C53: =((A53*$C$31+$D$31)*A53+$E$31)*A53+$F$31 -> 2.128036 | D53: =EXP(C53) -> 8.3983566 | E53: =$C$36*B53+$D$36 -> 0.26960301 | F53: 0 | G53: =NORMDIST(LN(G$41),$C53,$E53,TRUE) -> 3.4857939e-06 | H53: =NORMDIST(LN(H$41),$C53,$E53,TRUE) -> 0.33737855 | I53: =NORMDIST(LN(I$41),$C53,$E53,TRUE) -> 0.92990777 | J53: =NORMDIST(LN(J$41),$C53,$E53,TRUE) -> 0.9967667 | K53: =NORMDIST(LN(K$41),$C53,$E53,TRUE) -> 0.99975546 | L53: =NORMDIST(LN(L$41),$C53,$E53,TRUE) -> 0.99998988 | M53: =NORMDIST(LN(M$41),$C53,$E53,TRUE) -> 0.99999953 | N53: =NORMDIST(LN(N$41),$C53,$E53,TRUE) -> 0.99999997 | ... Z53: =NORMDIST(LN(Z$41),$C53,$E53,TRUE) -> 1 | AA53: 1
... A101: 6 | B101: =LN(A101) -> 1.7917595 | C101: =((A101*$C$31+$D$31)*A101+$E$31)*A101+$F$31 -> 4.7754027 | D101: =EXP(C101) -> 118.55805 | E101: =$C$36*B101+$D$36 -> 0.092279869 | F101: 0 | G101: =NORMDIST(LN(G$41),$C101,$E101,TRUE) -> 0 | H101: =NORMDIST(LN(H$41),$C101,$E101,TRUE) -> 6.3872194e-197 | I101: =NORMDIST(LN(I$41),$C101,$E101,TRUE) -> 1.434688e-131 | J101: =NORMDIST(LN(J$41),$C101,$E101,TRUE) -> 8.8004764e-96 | K101: =NORMDIST(LN(K$41),$C101,$E101,TRUE) -> 9.972337e-77 | L101: =NORMDIST(LN(L$41),$C101,$E101,TRUE) -> 1.4026799e-59 | M101: =NORMDIST(LN(M$41),$C101,$E101,TRUE) -> 4.416385e-47 | N101: =NORMDIST(LN(N$41),$C101,$E101,TRUE) -> 1.2613056e-37 | ... Z101: =NORMDIST(LN(Z$41),$C101,$E101,TRUE) -> 0.012846551 | AA101: 1
A104: Probability Distribution for CPU to fall into bin ventered at each 5% step
A105: EPH(in M) | B105: 0 | C105: 5 | D105: 10 | E105: 15 | F105: 20 | G105: 25 | H105: 30 | I105: 35 | J105: 40 | K105: 45 | L105: 50 | M105: 55 | N105: 60 | O105: 65 | P105: 70 | Q105: 75 | R105: 80 | S105: 85 | T105: 90 | U105: 95 | V105: 100
A106: 0.1 | B106: 0 | C106: =H42-G42 -> 0.54647439 | D106: =I42-H42 -> 0.03168104 | E106: =J42-I42 -> 0.002547334 | F106: =K42-J42 -> 0.00028054347 | G106: =L42-K42 -> 6.9207014e-05 | H106: =M42-L42 -> 1.3224707e-05 | I106: =N42-M42 -> 3.0063305e-06 | J106: =O42-N42 -> 7.8390607e-07 | ... V106: =AA42-Z42 -> 3.5498715e-11
...
