Workbook

Sheet CMCPU
A1: Soak Test - 25th and 26th Dec 2010 | D1: 0.7 | E1: 1 | F1: 1 | G1: 1 | H1: 1 | I1: 1.2 | J1: 70% - 1st | K1: 70% -2nd | L1: 70% - 3rd | M1: 70% - 4th | N1: 70% - 5th | O1: 70% - 6th | P1: 70% - 7th | Q1: 70% - 8th | R1: 70% - 9th | S1: 70% - 10th | T1: 70% - 11th | U1: 70% - 12th | V1: 70% - 13th | W1: 70% - 14th | X1: 70% - 15th | Y1: 70% - 16th | Z1: 70% - 17th | AA1: SOAK TEST ENDS
D2: 0330-0430 | E2: 0430-0530 | F2: 0530-0630 | G2: 0630-0730 | H2: 0730-0830 | I2: 0830-0930 | J2: 0930-1030 | K2: 1030-1130 | L2: 1130-1230 | M2: 1230-1330 | N2: 1330-1430 | O2: 1430-1530 | P2: 1530-1630 | Q2: 1630-1730 | R2: 1730-1830 | S2: 1830-1930 | T2: 1930-2030 | U2: 2030-2130 | V2: 2130-2230 | W2: 2230-2330 | X2: 2330-0030 | Y2: 0030-0130 | Z2: 0230--0330
B3: SYSTEM | C3: CPU Max | D3: 0.6401 | E3: 0.6544 | F3: 0.6793 | G3: 0.6761 | H3: 0.6851 | I3: 0.679 | J3: 0.679 | K3: 0.5634 | L3: 0.6752 | M3: 0.6456 | N3: 0.6668 | O3: 0.6586 | P3: 0.6593 | Q3: 0.6658 | R3: 0.6716 | S3: 0.6618 | T3: 0.6615 | U3: 0.6927 | V3: 0.6622 | W3: 0.6036 | X3: 0.6725 | Y3: 0.6714 | Z3: 0.6707
B4: CM | C4: CPU Average | D4: 0.5353 | E4: 0.5634 | F4: 0.6553 | G4: 0.6597 | H4: 0.6382 | I4: 0.3588 | J4: 0.3588 | K4: 0.2456 | L4: 0.4836 | M4: 0.6263 | N4: 0.598 | O4: 0.6438 | P4: 0.6458 | Q4: 0.6506 | R4: 0.6503 | S4: 0.6455 | T4: 0.645 | U4: 0.6528 | V4: 0.6347 | W4: 0.5938 | X4: 0.4712 | Y4: 0.538 | Z4: 0.5832
C5: CPU Min | D5: 0.0164 | E5: 0.1678 | F5: 0.6389 | G5: 0.6454 | H5: 0.378 | I5: 0.1155 | J5: 0.1155 | K5: 0.0154 | L5: 0.0223 | M5: 0.6094 | N5: 0.3391 | O5: 0.6351 | P5: 0.629 | Q5: 0.6374 | R5: 0.6361 | S5: 0.6369 | T5: 0.6356 | U5: 0.6324 | V5: 0.5975 | W5: 0.5652 | X5: 0.0822 | Y5: 0.347 | Z5: 0.499

Sheet Load
A1: Soak Test Online Volumes (Note: All the CM APIs mentioned below are synchronous call from CM)
A2: Module | B2: Business Process | C2: Average SLA latency (seconds) | D2: Production Volumes (TPS) | E2: Limiting Factor in PET | F2: # of Servers in Prod | G2: # of Servers in PET | H2: PET Comparison to Prod (Scale Down Factor %) | I2: Targeted TPS (20% Peak load) | J2: Targeted TPS (50% Peak load) | K2: Targeted TPS (70% Peak load) | L2: Targeted TPS (100% Peak load) | M2: Targeted TPS (120% Peak load) | N2: Pass Criteria
I3: 0.2 | J3: 0.5 | K3: 0.7 | L3: 1 | M3: 1.2
A4: CM - Prepaid | B4: Restore Subscriber | C4: 1.5 | D4: 4 | E4: CM Servers | F4: 5 | G4: 2 | H4: 0.4 | I4: 0 | J4: 0 | K4: 0 | L4: 1.6 | M4: 0 | N4: CPU Utilization should not be more than 70%
B5: Add Favorite Number | C5: 1.5 | D5: 2 | F5: 5 | G5: 2 | H5: 0.4 | I5: 0 | J5: 0 | K5: 0 | L5: 0.8 | M5: 0
B6: Add Offer | C6: 2 | D6: 32 | E6: RB Servers | F6: 22 | G6: 2 | H6: 0.1 | I6: 0.64 | J6: 1.6 | K6: 2.24 | L6: 3.2 | M6: 9.6
B7: Get Subscriber Offer | C7: 1.5 | D7: 62 | E7: CM Servers | F7: 5 | G7: 2 | H7: 0.4 | I7: 3.76 | J7: 8.4 | K7: 11 | L7: 24.8 | M7: 39.04
B8: Change Price Plan | C8: 1.5 | D8: 26 | F8: 5 | G8: 2 | H8: 0.4 | I8: 0 | J8: 0 | K8: 0 | L8: 10.4 | M8: 0
B9: Query Favorite Number | C9: 1.5 | D9: 1 | F9: 5 | G9: 2 | H9: 0.4 | I9: 3 | J9: 8 | K9: 12.1 | L9: 0.4 | M9: 39.04
B10: Remove Favorite Number | C10: 1.5 | D10: 1 | F10: 5 | G10: 2 | H10: 0.4 | I10: 0 | J10: 0 | K10: 0 | L10: 0.4 | M10: 0
B11: Replace Favorite Number | C11: 1.5 | D11: 1 | F11: 5 | G11: 2 | H11: 0.4 | I11: 0 | J11: 0 | K11: 0 | L11: 0.4 | M11: 0
B12: Suspend Subscriber | C12: 1.5 | D12: 4 | F12: 5 | G12: 2 | H12: 0.4 | I12: 0 | J12: 0 | K12: 0 | L12: 1.6 | M12: 0
B13: Remove Offer | C13: 1.5 | D13: 10 | F13: 5 | G13: 2 | H13: 0.4 | I13: 0 | J13: 0 | K13: 0 | L13: 4 | M13: 0
B14: Resume Subscriber | C14: 1.5 | D14: 4 | F14: 5 | G14: 2 | H14: 0.4 | I14: 0 | J14: 0 | K14: 0 | L14: 1.6 | M14: 0
B15: Update MSISDN NameAddress | C15: 1.5 | D15: 7 | F15: 5 | G15: 2 | H15: 0.4 | I15: 3 | J15: 8 | K15: 11 | L15: 2.8 | M15: 3.36
B16: Total TPS | D16: 154 | I16: 10.6 | J16: 26.5 | K16: 37.04 | L16: 53 | M16: 92.24
A17: RPL - Prepaid | B17: Get Balance Info | C17: 1.5 | D17: 105 | E17: RB Servers | F17: 22 | G17: 2 | H17: 0.1 | I17: 2.1 | J17: 5.25 | K17: 7.35 | L17: 10.5 | M17: 12.6
B18: Balance Transfer | C18: 4 | D18: 14 | F18: 22 | G18: 2 | H18: 0.1 | I18: 0.28 | J18: 0.7 | K18: 0.98 | L18: 1.4 | M18: 1.68
B19: Update Expiry Date | C19: 1.5 | D19: 4 | F19: 22 | G19: 2 | H19: 0.1 | I19: 0.08 | J19: 0.2 | K19: 0.28 | L19: 0.4 | M19: 0.48
B20: Balance Adjustment | C20: 4 | D20: 4 | F20: 22 | G20: 2 | H20: 0.1 | I20: 0.08 | J20: 0.2 | K20: 0.28 | L20: 0.4 | M20: 0.48
B21: Total TPS | D21: 127 | I21: 2.54 | J21: 6.35 | K21: 8.89 | L21: 12.7 | M21: 15.24
A22: CM - PostPaid | B22: AddOffer | C22: 2 | D22: 5 | E22: RB Servers | F22: 22 | G22: 2 | H22: 0.1 | I22: 0.1 | J22: 0.25 | K22: 0.35 | L22: 0.5 | M22: 0.6
B23: GetSubscriberOffers | C23: 1.5 | D23: 5 | E23: CM Servers | F23: 5 | G23: 2 | H23: 0.4 | I23: 0.4 | J23: 1 | K23: 1.4 | L23: 2 | M23: 2.4
B24: CM_Getmsisdn_language | C24: 1.5 | D24: 5 | F24: 5 | G24: 2 | H24: 0.4 | I24: 0.4 | J24: 1 | K24: 1.4 | L24: 2 | M24: 2.4
B25: CM_GetMSISDNProfile | C25: 1.5 | D25: 5 | F25: 5 | G25: 2 | H25: 0.4 | I25: 0.4 | J25: 1 | K25: 1.4 | L25: 2 | M25: 2.4
B26: CM_GetBAfromPrimaryMsisdn | C26: 1.5 | D26: 5 | F26: 5 | G26: 2 | H26: 0.4 | I26: 0.4 | J26: 1 | K26: 1.4 | L26: 2 | M26: 2.4
B27: CM_GetPrimary_MSISDNFROM_BA | C27: 1.5 | D27: 5 | F27: 5 | G27: 2 | H27: 0.4 | I27: 0.4 | J27: 1 | K27: 1.4 | L27: 2 | M27: 2.4
B28: Total TPS | D28: 30 | I28: 2.1 | J28: 5.25 | K28: 7.35 | L28: 10.5 | M28: 12.6

Sheet CMALL
A4: Date-Time | B4: Time | C4: Sample | D4: CM Sample | E4: Load | F4: CM CPU MAX | G4: CM CPU AVG | H4: DB CPU%
A5: 12/25/201009:30:00 | B5: =TIMEVALUE(MID(A5,11,8)) -> 0.39583333 | C5: 1 | D5: =TRUNC((C5-1)/12) -> 0 | E5: 0.71 | F5: =OFFSET(CMCPU!$J$3,0,$D5,1,1) -> 0.679 | G5: =OFFSET(CMCPU!$J$4,0,$D5,1,1) -> 0.3588 | H5: 13.99
A6: 12/25/201009:35:00 | B6: =TIMEVALUE(MID(A6,11,8)) -> 0.39930556 | C6: 2 | D6: =TRUNC((C6-1)/12) -> 0 | E6: 0.71 | F6: =OFFSET(CMCPU!$J$3,0,$D6,1,1) -> 0.679 | G6: =OFFSET(CMCPU!$J$4,0,$D6,1,1) -> 0.3588 | H6: 12.48
A7: 12/25/201009:40:00 | B7: =TIMEVALUE(MID(A7,11,8)) -> 0.40277778 | C7: 3 | D7: =TRUNC((C7-1)/12) -> 0 | E7: 0.71 | F7: =OFFSET(CMCPU!$J$3,0,$D7,1,1) -> 0.679 | G7: =OFFSET(CMCPU!$J$4,0,$D7,1,1) -> 0.3588 | H7: 9.22
A8: 12/25/201009:45:00 | B8: =TIMEVALUE(MID(A8,11,8)) -> 0.40625 | C8: 4 | D8: =TRUNC((C8-1)/12) -> 0 | E8: 0.71 | F8: =OFFSET(CMCPU!$J$3,0,$D8,1,1) -> 0.679 | G8: =OFFSET(CMCPU!$J$4,0,$D8,1,1) -> 0.3588 | H8: 8.61
A9: 12/25/201009:50:01 | B9: =TIMEVALUE(MID(A9,11,8)) -> 0.4097338 | C9: 5 | D9: =TRUNC((C9-1)/12) -> 0 | E9: 0.71 | F9: =OFFSET(CMCPU!$J$3,0,$D9,1,1) -> 0.679 | G9: =OFFSET(CMCPU!$J$4,0,$D9,1,1) -> 0.3588 | H9: 8.68
A10: 12/25/201009:55:00 | B10: =TIMEVALUE(MID(A10,11,8)) -> 0.41319444 | C10: 6 | D10: =TRUNC((C10-1)/12) -> 0 | E10: 0.71 | F10: =OFFSET(CMCPU!$J$3,0,$D10,1,1) -> 0.679 | G10: =OFFSET(CMCPU!$J$4,0,$D10,1,1) -> 0.3588 | H10: 10.49
A11: 12/25/201010:00:00 | B11: =TIMEVALUE(MID(A11,11,8)) -> 0.41666667 | C11: 7 | D11: =TRUNC((C11-1)/12) -> 0 | E11: 0.71 | F11: =OFFSET(CMCPU!$J$3,0,$D11,1,1) -> 0.679 | G11: =OFFSET(CMCPU!$J$4,0,$D11,1,1) -> 0.3588 | H11: 6.09
A12: 12/25/201010:05:00 | B12: =TIMEVALUE(MID(A12,11,8)) -> 0.42013889 | C12: 8 | D12: =TRUNC((C12-1)/12) -> 0 | E12: 0.71 | F12: =OFFSET(CMCPU!$J$3,0,$D12,1,1) -> 0.679 | G12: =OFFSET(CMCPU!$J$4,0,$D12,1,1) -> 0.3588 | H12: 7.8
A13: 12/25/201010:10:00 | B13: =TIMEVALUE(MID(A13,11,8)) -> 0.42361111 | C13: 9 | D13: =TRUNC((C13-1)/12) -> 0 | E13: 0.71 | F13: =OFFSET(CMCPU!$J$3,0,$D13,1,1) -> 0.679 | G13: =OFFSET(CMCPU!$J$4,0,$D13,1,1) -> 0.3588 | H13: 4.48
A14: 12/25/201010:15:00 | B14: =TIMEVALUE(MID(A14,11,8)) -> 0.42708333 | C14: 10 | D14: =TRUNC((C14-1)/12) -> 0 | E14: 0.71 | F14: =OFFSET(CMCPU!$J$3,0,$D14,1,1) -> 0.679 | G14: =OFFSET(CMCPU!$J$4,0,$D14,1,1) -> 0.3588 | H14: 8.3
A15: 12/25/201010:20:00 | B15: =TIMEVALUE(MID(A15,11,8)) -> 0.43055556 | C15: 11 | D15: =TRUNC((C15-1)/12) -> 0 | E15: 0.71 | F15: =OFFSET(CMCPU!$J$3,0,$D15,1,1) -> 0.679 | G15: =OFFSET(CMCPU!$J$4,0,$D15,1,1) -> 0.3588 | H15: 7.37
A16: 12/25/201010:25:00 | B16: =TIMEVALUE(MID(A16,11,8)) -> 0.43402778 | C16: 12 | D16: =TRUNC((C16-1)/12) -> 0 | E16: 0.71 | F16: =OFFSET(CMCPU!$J$3,0,$D16,1,1) -> 0.679 | G16: =OFFSET(CMCPU!$J$4,0,$D16,1,1) -> 0.3588 | H16: 6.93
... A208: 12/26/201002:25:00 | B208: =TIMEVALUE(MID(A208,11,8)) -> 0.10069444 | C208: 204 | D208: =TRUNC((C208-1)/12) -> 16 | E208: 0.71 | F208: =OFFSET(CMCPU!$J$3,0,$D208,1,1) -> 0.6707 | G208: =OFFSET(CMCPU!$J$4,0,$D208,1,1) -> 0.5832 | H208: 12.2
A209: 12/25/201008:30:00 | B209: =TIMEVALUE(MID(A209,11,8)) -> 0.35416667 | C209: 1 | D209: =TRUNC((C209-1)/12) -> 0 | E209: 1.2 | F209: 0.679 | G209: 0.3588 | H209: 24.16
A210: 12/25/201008:35:00 | B210: =TIMEVALUE(MID(A210,11,8)) -> 0.35763889 | C210: 2 | D210: =TRUNC((C210-1)/12) -> 0 | E210: 1.2 | F210: 0.679 | G210: 0.3588 | H210: 6.75
A211: 12/25/201008:40:00 | B211: =TIMEVALUE(MID(A211,11,8)) -> 0.36111111 | C211: 3 | D211: =TRUNC((C211-1)/12) -> 0 | E211: 1.2 | F211: 0.679 | G211: 0.3588 | H211: 9.16
A212: 12/25/201008:45:00 | B212: =TIMEVALUE(MID(A212,11,8)) -> 0.36458333 | C212: 4 | D212: =TRUNC((C212-1)/12) -> 0 | E212: 1.2 | F212: 0.679 | G212: 0.3588 | H212: 12.3
A213: 12/25/201008:50:00 | B213: =TIMEVALUE(MID(A213,11,8)) -> 0.36805556 | C213: 5 | D213: =TRUNC((C213-1)/12) -> 0 | E213: 1.2 | F213: 0.679 | G213: 0.3588 | H213: 12.07
A214: 12/25/201008:55:00 | B214: =TIMEVALUE(MID(A214,11,8)) -> 0.37152778 | C214: 6 | D214: =TRUNC((C214-1)/12) -> 0 | E214: 1.2 | F214: 0.679 | G214: 0.3588 | H214: 12.55
A215: 12/25/201009:00:00 | B215: =TIMEVALUE(MID(A215,11,8)) -> 0.375 | C215: 7 | D215: =TRUNC((C215-1)/12) -> 0 | E215: 1.2 | F215: 0.679 | G215: 0.3588 | H215: 13.54
A216: 12/25/201009:05:00 | B216: =TIMEVALUE(MID(A216,11,8)) -> 0.37847222 | C216: 8 | D216: =TRUNC((C216-1)/12) -> 0 | E216: 1.2 | F216: 0.679 | G216: 0.3588 | H216: 13.69
A217: 12/25/201009:10:00 | B217: =TIMEVALUE(MID(A217,11,8)) -> 0.38194444 | C217: 9 | D217: =TRUNC((C217-1)/12) -> 0 | E217: 1.2 | F217: 0.679 | G217: 0.3588 | H217: 12.92
A218: 12/25/201009:15:00 | B218: =TIMEVALUE(MID(A218,11,8)) -> 0.38541667 | C218: 10 | D218: =TRUNC((C218-1)/12) -> 0 | E218: 1.2 | F218: 0.679 | G218: 0.3588 | H218: 12.68
A219: 12/25/201009:20:00 | B219: =TIMEVALUE(MID(A219,11,8)) -> 0.38888889 | C219: 11 | D219: =TRUNC((C219-1)/12) -> 0 | E219: 1.2 | F219: 0.679 | G219: 0.3588 | H219: 13.03
A220: 12/25/201009:25:00 | B220: =TIMEVALUE(MID(A220,11,8)) -> 0.39236111 | C220: 12 | D220: =TRUNC((C220-1)/12) -> 0 | E220: 1.2 | F220: 0.679 | G220: 0.3588 | H220: 13.85
... A241: 12/25/201006:10:00 | B241: =TIMEVALUE(MID(A241,11,8)) -> 0.25694444 | C241: 21 | D241: =TRUNC((C241-1)/12) -> 1 | E241: 1 | F241: 0.6793 | G241: 0.6553 | H241: 18.14
A242: 12/25/201006:15:00 | B242: =TIMEVALUE(MID(A242,11,8)) -> 0.26041667 | C242: 22 | D242: =TRUNC((C242-1)/12) -> 1 | E242: 1 | F242: 0.6793 | G242: 0.6553 | H242: 18.76 | AB242: #N/A
A243: 12/25/201006:20:00 | B243: =TIMEVALUE(MID(A243,11,8)) -> 0.26388889 | C243: 23 | D243: =TRUNC((C243-1)/12) -> 1 | E243: 1 | F243: 0.6793 | G243: 0.6553 | H243: 54.16 | AB243: =AVERAGE(N243:N244) -> #DIV/0!
A244: 12/25/201006:25:00 | B244: =TIMEVALUE(MID(A244,11,8)) -> 0.26736111 | C244: 24 | D244: =TRUNC((C244-1)/12) -> 1 | E244: 1 | F244: 0.6793 | G244: 0.6553 | H244: 17.64 | AB244: =AVERAGE(N244:N245) -> #DIV/0!
A245: 12/25/201006:30:00 | B245: =TIMEVALUE(MID(A245,11,8)) -> 0.27083333 | C245: 25 | D245: =TRUNC((C245-1)/12) -> 2 | E245: 1 | F245: 0.6793 | G245: 0.6553 | H245: 20.21 | AB245: =AVERAGE(N245:N246) -> #DIV/0!
A246: 12/25/201006:35:00 | B246: =TIMEVALUE(MID(A246,11,8)) -> 0.27430556 | C246: 26 | D246: =TRUNC((C246-1)/12) -> 2 | E246: 1 | F246: 0.6761 | G246: 0.6597 | H246: 18.75 | AB246: =AVERAGE(N246:N247) -> #DIV/0!
A247: 12/25/201006:40:00 | B247: =TIMEVALUE(MID(A247,11,8)) -> 0.27777778 | C247: 27 | D247: =TRUNC((C247-1)/12) -> 2 | E247: 1 | F247: 0.6761 | G247: 0.6597 | H247: 55.16 | AB247: =AVERAGE(N247:N248) -> #DIV/0!
A248: 12/25/201006:45:00 | B248: =TIMEVALUE(MID(A248,11,8)) -> 0.28125 | C248: 28 | D248: =TRUNC((C248-1)/12) -> 2 | E248: 1 | F248: 0.6761 | G248: 0.6597 | H248: 19.93 | AB248: =AVERAGE(N248:N249) -> #DIV/0!
A249: 12/25/201006:50:00 | B249: =TIMEVALUE(MID(A249,11,8)) -> 0.28472222 | C249: 29 | D249: =TRUNC((C249-1)/12) -> 2 | E249: 1 | F249: 0.6761 | G249: 0.6597 | H249: 17.76 | AB249: =AVERAGE(N249:N250) -> #DIV/0!
A250: 12/25/201006:55:00 | B250: =TIMEVALUE(MID(A250,11,8)) -> 0.28819444 | C250: 30 | D250: =TRUNC((C250-1)/12) -> 2 | E250: 1 | F250: 0.6761 | G250: 0.6597 | H250: 22.83 | AB250: =AVERAGE(N250:N251) -> #DIV/0!
A251: 12/25/201007:00:00 | B251: =TIMEVALUE(MID(A251,11,8)) -> 0.29166667 | C251: 31 | D251: =TRUNC((C251-1)/12) -> 2 | E251: 1 | F251: 0.6761 | G251: 0.6597 | H251: 45.78 | AB251: =AVERAGE(N251:N252) -> #DIV/0!
A252: 12/25/201007:05:00 | B252: =TIMEVALUE(MID(A252,11,8)) -> 0.29513889 | C252: 32 | D252: =TRUNC((C252-1)/12) -> 2 | E252: 1 | F252: 0.6761 | G252: 0.6597 | H252: 19.37 | AB252: =AVERAGE(N252:N253) -> #DIV/0!
A253: 12/25/201007:10:00 | B253: =TIMEVALUE(MID(A253,11,8)) -> 0.29861111 | C253: 33 | D253: =TRUNC((C253-1)/12) -> 2 | E253: 1 | F253: 0.6761 | G253: 0.6597 | H253: 20.19 | AB253: =AVERAGE(N253:N254) -> #DIV/0!
A254: 12/25/201007:15:00 | B254: =TIMEVALUE(MID(A254,11,8)) -> 0.30208333 | C254: 34 | D254: =TRUNC((C254-1)/12) -> 2 | E254: 1 | F254: 0.6761 | G254: 0.6597 | H254: 19.16 | AB254: =AVERAGE(N254:N255) -> #DIV/0!
...

Sheet Sheet2
B3: Values
A4: Row Labels | B4: Average of Log CM CPU AVG | C4: StdDev of Log CM CPU AVG
A5: 0.7 | B5: -0.62492794 | C5: 0
A6: 0.71 | B6: -0.5920925 | C6: 0.25659073
A7: 1 | B7: -0.46797243 | C7: 0.066284624
A8: 1.2 | B8: -1.0249901 | C8: 0
A9: (blank)
A10: Grand Total | B10: -0.59075567 | C10: 0.24548658

Sheet CMVALS
A1: CM Sample(Hour) | B1: Load | C1: CM CPU MAX | D1: CM CPU AVG | E1: CM DB CPU% | F1: Log CM CPU AVG
A2: 0 | B2: 0.71 | C2: 0.679 | D2: 0.3588 | E2: 13.99 | F2: =LN(D2) -> -1.0249901
A3: 0 | B3: 0.71 | C3: 0.679 | D3: 0.3588 | E3: 12.48 | F3: =LN(D3) -> -1.0249901
A4: 0 | B4: 0.71 | C4: 0.679 | D4: 0.3588 | E4: 9.22 | F4: =LN(D4) -> -1.0249901
A5: 0 | B5: 0.71 | C5: 0.679 | D5: 0.3588 | E5: 8.61 | F5: =LN(D5) -> -1.0249901
A6: 0 | B6: 0.71 | C6: 0.679 | D6: 0.3588 | E6: 8.68 | F6: =LN(D6) -> -1.0249901
A7: 0 | B7: 0.71 | C7: 0.679 | D7: 0.3588 | E7: 10.49 | F7: =LN(D7) -> -1.0249901
A8: 0 | B8: 0.71 | C8: 0.679 | D8: 0.3588 | E8: 6.09 | F8: =LN(D8) -> -1.0249901
A9: 0 | B9: 0.71 | C9: 0.679 | D9: 0.3588 | E9: 7.8 | F9: =LN(D9) -> -1.0249901
A10: 0 | B10: 0.71 | C10: 0.679 | D10: 0.3588 | E10: 4.48 | F10: =LN(D10) -> -1.0249901
A11: 0 | B11: 0.71 | C11: 0.679 | D11: 0.3588 | E11: 8.3 | F11: =LN(D11) -> -1.0249901
A12: 0 | B12: 0.71 | C12: 0.679 | D12: 0.3588 | E12: 7.37 | F12: =LN(D12) -> -1.0249901
A13: 0 | B13: 0.71 | C13: 0.679 | D13: 0.3588 | E13: 6.93 | F13: =LN(D13) -> -1.0249901
... A277: 0 | B277: 0.7 | C277: 0.6401 | D277: 0.5353 | E277: 11.3 | F277: =LN(D277) -> -0.62492794

Sheet PivotByLoad
B3: Values
A4: Row Labels | B4: Max of CM CPU MAX | C4: Max of CM CPU AVG | D4: Max of CM DB CPU% | E4: Average of CM DB CPU% | F4: StdDev of CM DB CPU% | G4: Average of CM CPU AVG | H4: StdDev of CM CPU AVG | I4: Average of CM CPU MAX | J4: StdDev of CM CPU MAX
A5: 0.7 | B5: 0.6401 | C5: 0.5353 | D5: 12.16 | E5: 10.280833 | F5: 0.89441152 | G5: 0.5353 | H5: 0 | I5: 0.6401 | J5: 0
A6: 0.71 | B6: 0.6927 | C6: 0.6528 | D6: 23 | E6: 12.090784 | F6: 2.3806348 | G6: 0.56864706 | H6: 0.11384671 | I6: 0.65774706 | J6: 0.029700816
A7: 1 | B7: 0.6851 | C7: 0.6597 | D7: 55.16 | E7: 22.52875 | F7: 10.734442 | G7: 0.62759167 | H7: 0.040315162 | I7: 0.67308542 | J7: 0.011938887
A8: 1.2 | B8: 0.679 | C8: 0.3588 | D8: 24.16 | E8: 13.058333 | F8: 4.0616853 | G8: 0.3588 | H8: 4.4928691e-09 | I8: 0.679 | J8: 0
A9: Grand Total | B9: 0.6927 | C9: 0.6597 | D9: 55.16 | E9: 13.869457 | F9: 6.3713875 | G9: 0.56832464 | H9: 0.11145333 | I9: 0.66057138 | J9: 0.027237792

Sheet PivotByVal
A1: Row Labels | B1: Average of CM DB CPU% | C1: StdDev of CM DB CPU% | D1: Average of CM CPU AVG | E1: StdDev of CM CPU AVG | F1: Average of CM CPU MAX | G1: StdDev of CM CPU MAX | H1: Max of CM CPU AVG | I1: Max of CM DB CPU%
A2: 0.7 | B2: =12.0907843137255/100 -> 0.12090784 | C2: =2.38063479809904/10 -> 0.23806348 | D2: 0.56864706 | E2: 0.11384671 | F2: 0.65774706 | G2: 0.029700816 | H2: 0.6528 | I2: =23/100 -> 0.23
A3: 1 | B3: =22.52875/100 -> 0.2252875 | C3: =10.7344422057266/10 -> 1.0734442 | D3: 0.62759167 | E3: 0.040315162 | F3: 0.67308542 | G3: 0.011938887 | H3: 0.6597 | I3: =55.16/100 -> 0.5516
A4: 1.2 | B4: =13.0583333333333/100 -> 0.13058333 | C4: =4.06168534955478/10 -> 0.40616853 | D4: 0.3588 | E4: 4.4928691e-09 | F4: 0.679 | G4: 0 | H4: 0.3588 | I4: =24.16/100 -> 0.2416

Sheet 2points
A1: Row Labels | B1: Average of CM DB CPU% | C1: StdDev of CM DB CPU% | D1: CMDB+3STD | E1: Column1 | F1: Average of CM CPU AVG | G1: StdDev of CM CPU AVG | H1: AVG+3STD | I1: AVG-3STD | J1: Average of CM CPU MAX | K1: StdDev of CM CPU MAX | L1: Max of CM CPU AVG | M1: Max of CM DB CPU%
A2: 0.7 | B2: =12.0907843137255/100 -> 0.12090784 | C2: =2.38063479809904/10 -> 0.23806348 | D2: =B2+3*C2 -> 0.83509828 | E2: =B2-3*C2 -> -0.5932826 | F2: 0.56864706 | G2: 0.11384671 | H2: =F2+3*G2 -> 0.91018719 | I2: =F2-3*G2 -> 0.22710693 | J2: 0.65774706 | K2: 0.029700816 | L2: 0.6528 | M2: =23/100 -> 0.23
A3: 1 | B3: =22.52875/100 -> 0.2252875 | C3: =10.7344422057266/10 -> 1.0734442 | D3: =B3+3*C3 -> 3.4456202 | E3: =B3-3*C3 -> -2.9950452 | F3: 0.62759167 | G3: 0.040315162 | H3: =F3+3*G3 -> 0.74853715 | I3: =F3-3*G3 -> 0.50664618 | J3: 0.67308542 | K3: 0.011938887 | L3: 0.6597 | M3: =55.16/100 -> 0.5516
A4: 1.2 | B4: =13.0583333333333/100 -> 0.13058333 | C4: =4.06168534955478/10 -> 0.40616853 | F4: 0.3588 | G4: 4.4928691e-09 | J4: 0.679 | K4: 0 | L4: 0.3588 | M4: =24.16/100 -> 0.2416

Sheet 2points log-normal
A1: Load | B1: LOGNORMAL Mean | C1: LogNormal sigma | D1: CM CPU AVG | E1: CM CPU STD | F1: CM CPU+3std | G1: CM CPU -3std
A2: 0.7 | B2: -0.5920925 | C2: 0.25659073 | D2: =EXP(B2+((C2*C2)/2)) -> 0.57168159 | E2: =(EXP(C2*C2)-1)*EXP(2*B2+C2*C2) -> 0.022241574 | F2: =D2+3*E2 -> 0.63840631 | G2: =D2-3*E2 -> 0.50495687
A3: 1 | B3: -0.46797243 | C3: 0.066284624 | D3: =EXP(B3+((C3*C3)/2)) -> 0.62764811 | E3: =(EXP(C3*C3)-1)*EXP(2*B3+C3*C3) -> 0.0017346524 | F3: =D3+3*E3 -> 0.63285207 | G3: =D3-3*E3 -> 0.62244416
